[{"type":"subscriptions","channels":[{"name":"full","product_ids":["BTC-USD","ETH-USD"]},{"name":"heartbeat","product_ids":["BTC-USD","ETH-USD"]}]},{"type":"done","side":"sell","product_id":"BTC-USD","time":"2020-06-27T04:02:06.870138Z","sequence":14946197681,"order_id":"28a8cac3-1452-49b4-8737-e4bc1942941f","reason":"canceled","price":"9158.89","remaining_size":"0.03275815"},{"type":"done","side":"buy","product_id":"ETH-USD","time":"2020-06-27T04:02:06.870535Z","sequence":9591230122,"order_id":"13c03732-bea5-4e94-a49f-b2f5102b7cf4","reason":"canceled","price":"229.53","remaining_size":"60"},{"type":"done","side":"buy","product_id":"ETH-USD","time":"2020-06-27T04:02:06.878397Z","sequence":9591230123,"order_id":"d59e1b28-ec7b-4eb2-a14a-8814ac95e536","reason":"canceled","price":"229.44","remaining_size":"8.59010797"},{"type":"done","side":"sell","product_id":"ETH-USD","time":"2020-06-27T04:02:06.881254Z","sequence":9591230124,"order_id":"94410013-8d64-4e3d-9ce7-56fa8b900390","reason":"canceled","price":"229.67","remaining_size":"43.498"},{"type":"received","side":"buy","product_id":"BTC-USD","time":"2020-06-27T04:02:06.885553Z","sequence":14946197682,"order_id":"8440210a-d78e-43a8-8855-b70e2f8b42f5","order_type":"limit","size":"0.04","price":"9158","client_oid":"17f5573a-80a8-4eef-a6ae-90ade0ff4e48"},{"type":"open","side":"buy","product_id":"BTC-USD","time":"2020-06-27T04:02:06.885553Z","sequence":14946197683,"price":"9158","order_id":"8440210a-d78e-43a8-8855-b70e2f8b42f5","remaining_size":"0.04"},{"type":"done","side":"sell","product_id":"BTC-USD","time":"2020-06-27T04:02:06.886279Z","sequence":14946197684,"order_id":"4d7875cb-efdf-4ced-802a-d663eae779d3","reason":"canceled","price":"9159.09","remaining_size":"0.544"},{"type":"done","side":"sell","product_id":"ETH-USD","time":"2020-06-27T04:02:06.887215Z","sequence":9591230125,"order_id":"c228f46d-b2e4-473f-b3df-12f53b61ca59","reason":"canceled","price":"229.66","remaining_size":"23.28875237"},{"type":"done","side":"sell","product_id":"BTC-USD","time":"2020-06-27T04:02:06.890571Z","sequence":14946197685,"order_id":"20749d33-2b82-4805-b9fe-7dde1be2ce53","reason":"canceled","price":"9161.84","remaining_size":"0.54"},{"type":"received","side":"sell","product_id":"BTC-USD","time":"2020-06-27T04:02:06.890739Z","sequence":14946197686,"order_id":"9af8436a-e00c-47df-8f93-85af770e2be7","order_type":"limit","size":"0.545","price":"9158.85","client_oid":"db64fc3f-058f-4d7c-ac2a-986f99f70573"},{"type":"open","side":"sell","product_id":"BTC-USD","time":"2020-06-27T04:02:06.890739Z","sequence":14946197687,"price":"9158.85","order_id":"9af8436a-e00c-47df-8f93-85af770e2be7","remaining_size":"0.545"},{"type":"done","side":"sell","product_id":"BTC-USD","time":"2020-06-27T04:02:06.891293Z","sequence":14946197688,"order_id":"7a5de5a3-7b24-4922-a885-aae395a35fbf","reason":"canceled","price":"9187.56","remaining_size":"0.04478512"},{"type":"received","side":"buy","product_id":"ETH-USD","time":"2020-06-27T04:02:06.897233Z","sequence":9591230126,"order_id":"558a9bc1-f110-42b6-a560-5deccfebdc8e","order_type":"limit","size":"8.59010797","price":"229.45","client_oid":"ff6a866b-ae61-5ad9-0414-789932000100"},{"type":"open","side":"buy","product_id":"ETH-USD","time":"2020-06-27T04:02:06.897233Z","sequence":9591230127,"price":"229.45","order_id":"558a9bc1-f110-42b6-a560-5deccfebdc8e","remaining_size":"8.59010797"},{"type":"received","side":"sell","product_id":"ETH-USD","time":"2020-06-27T04:02:06.899665Z","sequence":9591230128,"order_id":"e366d327-dbdc-4692-a1dd-1d6a4565393b","order_type":"limit","size":"16.66549821","price":"229.69","client_oid":"3ce3c752-458a-43fb-b884-9e98d44b4947"},{"type":"open","side":"sell","product_id":"ETH-USD","time":"2020-06-27T04:02:06.899665Z","sequence":9591230129,"price":"229.69","order_id":"e366d327-dbdc-4692-a1dd-1d6a4565393b","remaining_size":"16.66549821"},{"type":"received","side":"sell","product_id":"BTC-USD","time":"2020-06-27T04:02:06.901473Z","sequence":14946197689,"order_id":"e0f281d8-00fa-4c13-9c44-7e8428b9bb2c","order_type":"limit","size":"0.05441678","price":"9188.35","client_oid":"d111e026-5e8a-4c4a-a9a1-18d6bf29b0bd"},{"type":"open","side":"sell","product_id":"BTC-USD","time":"2020-06-27T04:02:06.901473Z","sequence":14946197690,"price":"9188.35","order_id":"e0f281d8-00fa-4c13-9c44-7e8428b9bb2c","remaining_size":"0.05441678"},{"type":"done","side":"sell","product_id":"ETH-USD","time":"2020-06-27T04:02:06.906246Z","sequence":9591230130,"order_id":"6a3e53aa-2201-4e62-bf7d-734bce07213e","reason":"canceled","price":"229.6","remaining_size":"17.25181591"},{"type":"done","side":"buy","product_id":"ETH-USD","time":"2020-06-27T04:02:06.920283Z","sequence":9591230131,"order_id":"3436aebf-268b-4345-8f7d-3eaa41aa2ae0","reason":"canceled","price":"229.17","remaining_size":"16.66589545"},{"type":"received","side":"buy","product_id":"BTC-USD","time":"2020-06-27T04:02:06.926977Z","sequence":14946197691,"order_id":"3ec2884f-7c5f-4330-952d-923ce33cbeab","order_type":"limit","size":"0.94488421","price":"9143.65","client_oid":"6f3ee0ad-00da-4fe6-b826-b874692c165c"},{"type":"open","side":"buy","product_id":"BTC-USD","time":"2020-06-27T04:02:06.926977Z","sequence":14946197692,"price":"9143.65","order_id":"3ec2884f-7c5f-4330-952d-923ce33cbeab","remaining_size":"0.94488421"},{"type":"received","side":"sell","product_id":"BTC-USD","time":"2020-06-27T04:02:06.931842Z","sequence":14946197693,"order_id":"6f4195a7-eba1-40a5-bc49-e9f1c0e8a7ea","order_type":"limit","size":"0.03275815","price":"9158.87","client_oid":"907b6ae6-bcbe-441a-b7bb-d932afbd3df8"},{"type":"open","side":"sell","product_id":"BTC-USD","time":"2020-06-27T04:02:06.931842Z","sequence":14946197694,"price":"9158.87","order_id":"6f4195a7-eba1-40a5-bc49-e9f1c0e8a7ea","remaining_size":"0.03275815"},{"type":"done","side":"sell","product_id":"BTC-USD","time":"2020-06-27T04:02:06.940652Z","sequence":14946197695,"order_id":"54f84ad6-8057-49fd-8643-9911c011c0a9","reason":"canceled","price":"9158.88","remaining_size":"0.7304137"},{"type":"done","side":"sell","product_id":"BTC-USD","time":"2020-06-27T04:02:06.947103Z","sequence":14946197696,"order_id":"e0f281d8-00fa-4c13-9c44-7e8428b9bb2c","reason":"canceled","price":"9188.35","remaining_size":"0.05441678"},{"type":"received","side":"buy","product_id":"ETH-USD","time":"2020-06-27T04:02:06.950556Z","sequence":9591230132,"order_id":"4ac74bb3-270f-4228-bfba-3a85de6f5a71","order_type":"limit","size":"16.66541968","price":"229.18","client_oid":"cce1dfcf-ffbd-4be0-b086-511907b9495c"},{"type":"open","side":"buy","product_id":"ETH-USD","time":"2020-06-27T04:02:06.950556Z","sequence":9591230133,"price":"229.18","order_id":"4ac74bb3-270f-4228-bfba-3a85de6f5a71","remaining_size":"16.66541968"},{"type":"done","side":"sell","product_id":"BTC-USD","time":"2020-06-27T04:02:06.951670Z","sequence":14946197697,"order_id":"6f4195a7-eba1-40a5-bc49-e9f1c0e8a7ea","reason":"canceled","price":"9158.87","remaining_size":"0.03275815"},{"type":"done","side":"sell","product_id":"ETH-USD","time":"2020-06-27T04:02:06.953023Z","sequence":9591230134,"order_id":"9b82a4d4-b1b2-4ffd-9d04-e35b37beb48b","reason":"canceled","price":"229.71","remaining_size":"19.98826192"},{"type":"received","side":"sell","product_id":"BTC-USD","time":"2020-06-27T04:02:06.957824Z","sequence":14946197698,"order_id":"85d606dc-199b-459d-897d-b042c866b3a0","order_type":"limit","size":"0.03369366","price":"9187.56","client_oid":"2a24f02e-f4f3-46b2-9954-006b178907b3"},{"type":"done","side":"sell","product_id":"ETH-USD","time":"2020-06-27T04:02:06.958131Z","sequence":9591230135,"order_id":"40d1f3a5-6ce2-4158-a617-d393f9f89c51","reason":"canceled","price":"230.4","remaining_size":"16.33863416"},{"type":"open","side":"sell","product_id":"BTC-USD","time":"2020-06-27T04:02:06.957824Z","sequence":14946197699,"price":"9187.56","order_id":"85d606dc-199b-459d-897d-b042c866b3a0","remaining_size":"0.03369366"},{"type":"received","side":"sell","product_id":"BTC-USD","time":"2020-06-27T04:02:06.958745Z","sequence":14946197700,"order_id":"8c0f4f75-abd7-4bcf-bfd4-4855bb593325","order_type":"limit","size":"0.7304137","price":"9158.84","client_oid":"d6be1b95-64b5-8c37-ee75-099932005000"},{"type":"open","side":"sell","product_id":"BTC-USD","time":"2020-06-27T04:02:06.958745Z","sequence":14946197701,"price":"9158.84","order_id":"8c0f4f75-abd7-4bcf-bfd4-4855bb593325","remaining_size":"0.7304137"},{"type":"received","side":"sell","product_id":"ETH-USD","time":"2020-06-27T04:02:06.970000Z","sequence":9591230136,"order_id":"518d8aca-bcd4-4618-af41-16cbc7e81df8","order_type":"limit","size":"17.90750108","price":"230.43","client_oid":"f5469219-a5d9-428a-8e61-a1c88c7130b6"},{"type":"open","side":"sell","product_id":"ETH-USD","time":"2020-06-27T04:02:06.970000Z","sequence":9591230137,"price":"230.43","order_id":"518d8aca-bcd4-4618-af41-16cbc7e81df8","remaining_size":"17.90750108"},{"type":"received","side":"sell","product_id":"ETH-USD","time":"2020-06-27T04:02:06.970000Z","sequence":9591230138,"order_id":"11304123-b773-4206-af3d-440dd7cb1ce3","order_type":"limit","size":"16.33863416","price":"230.16","client_oid":"43acbd67-496a-4ef9-a82a-4cdc7be360b5"},{"type":"open","side":"sell","product_id":"ETH-USD","time":"2020-06-27T04:02:06.970000Z","sequence":9591230139,"price":"230.16","order_id":"11304123-b773-4206-af3d-440dd7cb1ce3","remaining_size":"16.33863416"},{"type":"received","side":"sell","product_id":"ETH-USD","time":"2020-06-27T04:02:06.970000Z","sequence":9591230140,"order_id":"5c7475ab-09d2-400a-a378-3e6845717c6e","order_type":"limit","size":"19.98826192","price":"229.64","client_oid":"86e4219f-a714-4453-9d38-6196ddb57977"},{"type":"open","side":"sell","product_id":"ETH-USD","time":"2020-06-27T04:02:06.970000Z","sequence":9591230141,"price":"229.64","order_id":"5c7475ab-09d2-400a-a378-3e6845717c6e","remaining_size":"19.98826192"},{"type":"done","side":"sell","product_id":"ETH-USD","time":"2020-06-27T04:02:06.974140Z","sequence":9591230142,"order_id":"8528d6dc-15b1-425f-84fc-a747196a1cb0","reason":"canceled","price":"229.8","remaining_size":"26.81228502"},{"type":"done","side":"sell","product_id":"ETH-USD","time":"2020-06-27T04:02:06.978324Z","sequence":9591230143,"order_id":"5e1073c1-7085-4e83-8656-00351f3319b0","reason":"canceled","price":"229.95","remaining_size":"15.99683163"},{"type":"done","side":"sell","product_id":"ETH-USD","time":"2020-06-27T04:02:06.982644Z","sequence":9591230144,"order_id":"df6204de-0936-4147-a03d-ffd7dc891319","reason":"canceled","price":"230.43","remaining_size":"15.74161016"},{"type":"received","side":"sell","product_id":"BTC-USD","time":"2020-06-27T04:02:06.986625Z","sequence":14946197702,"order_id":"956ef676-9180-4e6f-9178-423196cb21da","order_type":"limit","size":"0.03275815","price":"9158.84","client_oid":"907b6ae6-bcbe-441a-b7bb-d932afa5e4a4"},{"type":"open","side":"sell","product_id":"BTC-USD","time":"2020-06-27T04:02:06.986625Z","sequence":14946197703,"price":"9158.84","order_id":"956ef676-9180-4e6f-9178-423196cb21da","remaining_size":"0.03275815"},{"type":"done","side":"sell","product_id":"ETH-USD","time":"2020-06-27T04:02:06.987381Z","sequence":9591230145,"order_id":"0c5f51a9-642b-46c4-91e2-20e9c5aba2d4","reason":"canceled","price":"230.03","remaining_size":"20.1019618"},{"type":"done","side":"sell","product_id":"ETH-USD","time":"2020-06-27T04:02:06.991657Z","sequence":9591230146,"order_id":"b17b99a8-ce43-4532-a3ac-6a57e7e6bddf","reason":"canceled","price":"230.12","remaining_size":"17.22530817"},{"type":"done","side":"sell","product_id":"BTC-USD","time":"2020-06-27T04:02:07.004094Z","sequence":14946197704,"order_id":"9567d3bc-f388-4672-9f7a-48bab4c8b8af","reason":"canceled","price":"9162.69","remaining_size":"1.0969976"},{"type":"done","side":"sell","product_id":"BTC-USD","time":"2020-06-27T04:02:07.007070Z","sequence":14946197705,"order_id":"ba214bc6-87bf-456f-9b9e-7a56c82034e0","reason":"canceled","price":"9169.07","remaining_size":"1.10310182"},{"type":"done","side":"sell","product_id":"BTC-USD","time":"2020-06-27T04:02:07.011411Z","sequence":14946197706,"order_id":"8c0f4f75-abd7-4bcf-bfd4-4855bb593325","reason":"canceled","price":"9158.84","remaining_size":"0.7304137"},{"type":"received","side":"sell","product_id":"BTC-USD","time":"2020-06-27T04:02:07.015684Z","sequence":14946197707,"order_id":"d3b9e422-11c8-4545-8f6e-8b2d86c4c6c4","order_type":"limit","size":"1.10310182","price":"9166.2","client_oid":"20787951-6932-4eae-998e-ea8a5faba2b0"},{"type":"open","side":"sell","product_id":"BTC-USD","time":"2020-06-27T04:02:07.015684Z","sequence":14946197708,"price":"9166.2","order_id":"d3b9e422-11c8-4545-8f6e-8b2d86c4c6c4","remaining_size":"1.10310182"},{"type":"received","side":"sell","product_id":"BTC-USD","time":"2020-06-27T04:02:07.015684Z","sequence":14946197709,"order_id":"8eb208c6-b3e1-4621-84bb-0ffa0c35f649","order_type":"limit","size":"1.0969976","price":"9160.89","client_oid":"b8294540-470a-43cf-94a6-c9cb93ea9ab7"},{"type":"open","side":"sell","product_id":"BTC-USD","time":"2020-06-27T04:02:07.015684Z","sequence":14946197710,"price":"9160.89","order_id":"8eb208c6-b3e1-4621-84bb-0ffa0c35f649","remaining_size":"1.0969976"},{"type":"done","side":"sell","product_id":"BTC-USD","time":"2020-06-27T04:02:07.020530Z","sequence":14946197711,"order_id":"956ef676-9180-4e6f-9178-423196cb21da","reason":"canceled","price":"9158.84","remaining_size":"0.03275815"},{"type":"received","side":"sell","product_id":"BTC-USD","time":"2020-06-27T04:02:07.030879Z","sequence":14946197712,"order_id":"fe664a6e-fb80-4d04-a161-7cfeda625c8b","order_type":"limit","size":"0.7304137","price":"9158.83","client_oid":"fabc489b-5c92-cd63-a148-f99932005000"},{"type":"open","side":"sell","product_id":"BTC-USD","time":"2020-06-27T04:02:07.030879Z","sequence":14946197713,"price":"9158.83","order_id":"fe664a6e-fb80-4d04-a161-7cfeda625c8b","remaining_size":"0.7304137"},{"type":"done","side":"sell","product_id":"ETH-USD","time":"2020-06-27T04:02:07.049975Z","sequence":9591230147,"order_id":"2e3ee5e4-6d56-4daf-ae64-0ae31599f030","reason":"canceled","price":"229.79","remaining_size":"65.182"},{"type":"received","side":"sell","product_id":"ETH-USD","time":"2020-06-27T04:02:07.055266Z","sequence":9591230148,"order_id":"e15e31c1-d2a9-4f62-bdec-ad04ebf17176","order_type":"limit","size":"65.245","price":"229.7","client_oid":"5ebe8fcb-d27f-42aa-a798-cd111c23982f"},{"type":"open","side":"sell","product_id":"ETH-USD","time":"2020-06-27T04:02:07.055266Z","sequence":9591230149,"price":"229.7","order_id":"e15e31c1-d2a9-4f62-bdec-ad04ebf17176","remaining_size":"65.245"},{"type":"received","side":"sell","product_id":"BTC-USD","time":"2020-06-27T04:02:07.070138Z","sequence":14946197714,"order_id":"4ee9c652-5380-4ca9-bfd9-6966c316ef9a","order_type":"limit","size":"0.03275815","price":"9158.83","client_oid":"907b6ae6-bcbe-441a-b7bb-d932afdbf632"},{"type":"open","side":"sell","product_id":"BTC-USD","time":"2020-06-27T04:02:07.070138Z","sequence":14946197715,"price":"9158.83","order_id":"4ee9c652-5380-4ca9-bfd9-6966c316ef9a","remaining_size":"0.03275815"},{"type":"done","side":"sell","product_id":"BTC-USD","time":"2020-06-27T04:02:07.098398Z","sequence":14946197716,"order_id":"4ee9c652-5380-4ca9-bfd9-6966c316ef9a","reason":"canceled","price":"9158.83","remaining_size":"0.03275815"},{"type":"done","side":"sell","product_id":"ETH-USD","time":"2020-06-27T04:02:07.098902Z","sequence":9591230150,"order_id":"11304123-b773-4206-af3d-440dd7cb1ce3","reason":"canceled","price":"230.16","remaining_size":"16.33863416"},{"type":"done","side":"buy","product_id":"ETH-USD","time":"2020-06-27T04:02:07.111044Z","sequence":9591230151,"order_id":"6c0d0a0b-8cfb-48fd-a5d2-5cfa5e093eec","reason":"canceled","price":"229.14","remaining_size":"22.7107"},{"type":"received","side":"sell","product_id":"BTC-USD","time":"2020-06-27T04:02:07.133664Z","sequence":14946197717,"order_id":"9f20f60f-e110-445b-adb6-e61e788d07ae","order_type":"limit","size":"0.03275815","price":"9158.82","client_oid":"907b6ae6-bcbe-441a-b7bb-d932af461e13"},{"type":"open","side":"sell","product_id":"BTC-USD","time":"2020-06-27T04:02:07.133664Z","sequence":14946197718,"price":"9158.82","order_id":"9f20f60f-e110-445b-adb6-e61e788d07ae","remaining_size":"0.03275815"},{"type":"done","side":"sell","product_id":"BTC-USD","time":"2020-06-27T04:02:07.142681Z","sequence":14946197719,"order_id":"fe664a6e-fb80-4d04-a161-7cfeda625c8b","reason":"canceled","price":"9158.83","remaining_size":"0.7304137"},{"type":"received","side":"buy","product_id":"BTC-USD","time":"2020-06-27T04:02:07.162449Z","sequence":14946197720,"order_id":"984266ff-e8a2-4f06-8890-db856138615f","order_type":"limit","size":"0.05","price":"9153.08","client_oid":"212bc938-58a9-40fa-b28a-7e87eae4c988"},{"type":"open","side":"buy","product_id":"BTC-USD","time":"2020-06-27T04:02:07.162449Z","sequence":14946197721,"price":"9153.08","order_id":"984266ff-e8a2-4f06-8890-db856138615f","remaining_size":"0.05"},{"type":"received","side":"sell","product_id":"BTC-USD","time":"2020-06-27T04:02:07.163841Z","sequence":14946197722,"order_id":"0d8b62a1-b0cc-48c2-aa95-c1a4c3dff915","order_type":"limit","size":"0.7304137","price":"9158.81","client_oid":"fabc489b-5c92-cd63-a148-ba9932005000"},{"type":"open","side":"sell","product_id":"BTC-USD","time":"2020-06-27T04:02:07.163841Z","sequence":14946197723,"price":"9158.81","order_id":"0d8b62a1-b0cc-48c2-aa95-c1a4c3dff915","remaining_size":"0.7304137"},{"type":"done","side":"sell","product_id":"ETH-USD","time":"2020-06-27T04:02:07.169792Z","sequence":9591230152,"order_id":"c4089d38-1561-4a59-b904-dfb8d239b71f","reason":"canceled","price":"230.4","remaining_size":"22.17359095"},{"type":"done","side":"sell","product_id":"ETH-USD","time":"2020-06-27T04:02:07.174549Z","sequence":9591230153,"order_id":"518d8aca-bcd4-4618-af41-16cbc7e81df8","reason":"canceled","price":"230.43","remaining_size":"17.90750108"},{"type":"received","side":"sell","product_id":"ETH-USD","time":"2020-06-27T04:02:07.186460Z","sequence":9591230154,"order_id":"1b89cb8a-6a44-44e9-8401-a55038c13a0c","order_type":"limit","size":"20.41217742","price":"230.34","client_oid":"a1a32afc-c383-405e-a67b-5786eec317bd"},{"type":"open","side":"sell","product_id":"ETH-USD","time":"2020-06-27T04:02:07.186460Z","sequence":9591230155,"price":"230.34","order_id":"1b89cb8a-6a44-44e9-8401-a55038c13a0c","remaining_size":"20.41217742"},{"type":"received","side":"sell","product_id":"ETH-USD","time":"2020-06-27T04:02:07.186460Z","sequence":9591230156,"order_id":"da8cc565-9c83-4517-b2dd-3f24b6050c7c","order_type":"limit","size":"17.90750108","price":"230.12","client_oid":"ab2a34ed-0191-4c9b-8a40-22675d25d201"},{"type":"open","side":"sell","product_id":"ETH-USD","time":"2020-06-27T04:02:07.186460Z","sequence":9591230157,"price":"230.12","order_id":"da8cc565-9c83-4517-b2dd-3f24b6050c7c","remaining_size":"17.90750108"},{"type":"received","side":"sell","product_id":"ETH-USD","time":"2020-06-27T04:02:07.186460Z","sequence":9591230158,"order_id":"8e2e8cb8-a1bc-4d63-a561-6d1672932442","order_type":"limit","size":"22.17359095","price":"230.03","client_oid":"1a07ed75-f203-4647-8c24-2d2f5ab55c0e"},{"type":"open","side":"sell","product_id":"ETH-USD","time":"2020-06-27T04:02:07.186460Z","sequence":9591230159,"price":"230.03","order_id":"8e2e8cb8-a1bc-4d63-a561-6d1672932442","remaining_size":"22.17359095"},{"type":"received","side":"sell","product_id":"ETH-USD","time":"2020-06-27T04:02:07.186460Z","sequence":9591230160,"order_id":"112314ec-ec74-4e75-9c73-de6afc0ed60a","order_type":"limit","size":"16.33863416","price":"229.95","client_oid":"796113c5-ac66-4c17-b28e-f4124da65e2c"},{"type":"open","side":"sell","product_id":"ETH-USD","time":"2020-06-27T04:02:07.186460Z","sequence":9591230161,"price":"229.95","order_id":"112314ec-ec74-4e75-9c73-de6afc0ed60a","remaining_size":"16.33863416"},{"type":"received","side":"sell","product_id":"BTC-USD","time":"2020-06-27T04:02:07.187897Z","sequence":14946197724,"order_id":"41b002e6-b070-4638-9f69-a5c876422d85","order_type":"limit","size":"0.05","price":"9162.9","client_oid":"7c1c2aea-3e1b-4435-ad71-008e6d8870d6"},{"type":"open","side":"sell","product_id":"BTC-USD","time":"2020-06-27T04:02:07.187897Z","sequence":14946197725,"price":"9162.9","order_id":"41b002e6-b070-4638-9f69-a5c876422d85","remaining_size":"0.05"},{"type":"received","side":"sell","product_id":"ETH-USD","time":"2020-06-27T04:02:07.196876Z","sequence":9591230162,"order_id":"5336e384-82d5-458f-a04f-7921b5a672ce","order_type":"limit","size":"16.19573247","price":"230.43","client_oid":"ad91f56e-eb8c-412f-ab91-f7f8a7aeafdc"},{"type":"open","side":"sell","product_id":"ETH-USD","time":"2020-06-27T04:02:07.196876Z","sequence":9591230163,"price":"230.43","order_id":"5336e384-82d5-458f-a04f-7921b5a672ce","remaining_size":"16.19573247"},{"type":"done","side":"buy","product_id":"ETH-USD","time":"2020-06-27T04:02:07.201144Z","sequence":9591230164,"order_id":"b408a454-1f68-4890-9127-11bd1fd44e9c","reason":"canceled","price":"229.38","remaining_size":"25.08037886"},{"type":"received","side":"buy","product_id":"ETH-USD","time":"2020-06-27T04:02:07.211210Z","sequence":9591230165,"order_id":"cc20461a-dfc9-4c41-9ee2-cf0d4e82f58e","order_type":"limit","size":"25.08037886","price":"229.43","client_oid":"4807e095-a070-4274-83bb-c4711ebed718"},{"type":"open","side":"buy","product_id":"ETH-USD","time":"2020-06-27T04:02:07.211210Z","sequence":9591230166,"price":"229.43","order_id":"cc20461a-dfc9-4c41-9ee2-cf0d4e82f58e","remaining_size":"25.08037886"},{"type":"done","side":"sell","product_id":"BTC-USD","time":"2020-06-27T04:02:07.221309Z","sequence":14946197726,"order_id":"9f20f60f-e110-445b-adb6-e61e788d07ae","reason":"canceled","price":"9158.82","remaining_size":"0.03275815"},{"type":"done","side":"sell","product_id":"BTC-USD","time":"2020-06-27T04:02:07.230277Z","sequence":14946197727,"order_id":"85d606dc-199b-459d-897d-b042c866b3a0","reason":"canceled","price":"9187.56","remaining_size":"0.03369366"},{"type":"done","side":"buy","product_id":"ETH-USD","time":"2020-06-27T04:02:07.236365Z","sequence":9591230167,"order_id":"106a1607-5fb8-4c62-8ad1-639f6d24f429","reason":"canceled","price":"229.27","remaining_size":"20.85880051"},{"type":"received","side":"sell","product_id":"BTC-USD","time":"2020-06-27T04:02:07.240738Z","sequence":14946197728,"order_id":"b16c838d-2836-4ffa-9b95-9eb6fb5fdaf0","order_type":"limit","size":"0.05441678","price":"9188.35","client_oid":"31a184f9-963b-4afa-a49a-a39651f61723"},{"type":"open","side":"sell","product_id":"BTC-USD","time":"2020-06-27T04:02:07.240738Z","sequence":14946197729,"price":"9188.35","order_id":"b16c838d-2836-4ffa-9b95-9eb6fb5fdaf0","remaining_size":"0.05441678"},{"type":"received","side":"sell","product_id":"ETH-USD","time":"2020-06-27T04:02:07.247238Z","sequence":9591230168,"order_id":"b7194b33-f7d9-43cb-9a9e-d3460b94093e","order_type":"limit","size":"21.65783119","price":"230.43","client_oid":"e6c527a7-c0b6-4aab-8b4e-fb898b8bebfc"},{"type":"open","side":"sell","product_id":"ETH-USD","time":"2020-06-27T04:02:07.247238Z","sequence":9591230169,"price":"230.43","order_id":"b7194b33-f7d9-43cb-9a9e-d3460b94093e","remaining_size":"21.65783119"},{"type":"done","side":"buy","product_id":"ETH-USD","time":"2020-06-27T04:02:07.251951Z","sequence":9591230170,"order_id":"19a733bd-b0b9-47f3-8988-22796b4fce97","reason":"canceled","price":"229.17","remaining_size":"20.60127099"},{"type":"done","side":"buy","product_id":"ETH-USD","time":"2020-06-27T04:02:07.256617Z","sequence":9591230171,"order_id":"e3f7142d-026d-476f-9828-c8520a28002d","reason":"canceled","price":"229","remaining_size":"19.69455275"},{"type":"received","side":"sell","product_id":"BTC-USD","time":"2020-06-27T04:02:07.263893Z","sequence":14946197730,"order_id":"fb7416b0-fbf7-4799-ab62-e99dc5d5493d","order_type":"limit","size":"0.03275815","price":"9158.8","client_oid":"907b6ae6-bcbe-441a-b7bb-d932aff1a160"},{"type":"open","side":"sell","product_id":"BTC-USD","time":"2020-06-27T04:02:07.263893Z","sequence":14946197731,"price":"9158.8","order_id":"fb7416b0-fbf7-4799-ab62-e99dc5d5493d","remaining_size":"0.03275815"},{"type":"done","side":"sell","product_id":"BTC-USD","time":"2020-06-27T04:02:07.272857Z","sequence":14946197732,"order_id":"0d8b62a1-b0cc-48c2-aa95-c1a4c3dff915","reason":"canceled","price":"9158.81","remaining_size":"0.7304137"},{"type":"done","side":"sell","product_id":"BTC-USD","time":"2020-06-27T04:02:07.280231Z","sequence":14946197733,"order_id":"b16c838d-2836-4ffa-9b95-9eb6fb5fdaf0","reason":"canceled","price":"9188.35","remaining_size":"0.05441678"},{"type":"done","side":"sell","product_id":"BTC-USD","time":"2020-06-27T04:02:07.280835Z","sequence":14946197734,"order_id":"9af8436a-e00c-47df-8f93-85af770e2be7","reason":"canceled","price":"9158.85","remaining_size":"0.545"},{"type":"done","side":"buy","product_id":"BTC-USD","time":"2020-06-27T04:02:07.282936Z","sequence":14946197735,"order_id":"26e9f98e-45eb-4622-bbfd-140fdb832bbc","reason":"canceled","price":"9152.23","remaining_size":"0.838"},{"type":"received","side":"sell","product_id":"BTC-USD","time":"2020-06-27T04:02:07.285359Z","sequence":14946197736,"order_id":"544a63b5-0a73-431a-b7f7-2f503d398a19","order_type":"limit","size":"0.539","price":"9158.81","client_oid":"fb37bcb0-3523-4555-9f58-45e8524939e4"},{"type":"open","side":"sell","product_id":"BTC-USD","time":"2020-06-27T04:02:07.285359Z","sequence":14946197737,"price":"9158.81","order_id":"544a63b5-0a73-431a-b7f7-2f503d398a19","remaining_size":"0.539"},{"type":"done","side":"sell","product_id":"BTC-USD","time":"2020-06-27T04:02:07.287100Z","sequence":14946197738,"order_id":"7321ee64-a3db-46b8-86ab-600c902865f4","reason":"canceled","price":"9182.47","remaining_size":"1.107"},{"type":"done","side":"sell","product_id":"BTC-USD","time":"2020-06-27T04:02:07.290980Z","sequence":14946197739,"order_id":"ec27b9ed-c54b-4e78-b0cf-10733913ab2a","reason":"canceled","price":"9177.77","remaining_size":"0.732"},{"type":"received","side":"sell","product_id":"BTC-USD","time":"2020-06-27T04:02:07.292294Z","sequence":14946197740,"order_id":"29c59516-e515-43ae-a515-c7ec518eb309","order_type":"limit","size":"0.04478512","price":"9187.56","client_oid":"2ce4228f-d27c-4867-afba-89ad9f896929"},{"type":"open","side":"sell","product_id":"BTC-USD","time":"2020-06-27T04:02:07.292294Z","sequence":14946197741,"price":"9187.56","order_id":"29c59516-e515-43ae-a515-c7ec518eb309","remaining_size":"0.04478512"},{"type":"received","side":"sell","product_id":"BTC-USD","time":"2020-06-27T04:02:07.292434Z","sequence":14946197742,"order_id":"a2675055-fc5f-4977-849f-a66d87b9e68d","order_type":"limit","size":"0.7304137","price":"9158.79","client_oid":"fabc489b-5c92-cd63-a148-cb9932005000"},{"type":"open","side":"sell","product_id":"BTC-USD","time":"2020-06-27T04:02:07.292434Z","sequence":14946197743,"price":"9158.79","order_id":"a2675055-fc5f-4977-849f-a66d87b9e68d","remaining_size":"0.7304137"},{"type":"done","side":"buy","product_id":"BTC-USD","time":"2020-06-27T04:02:07.295703Z","sequence":14946197744,"order_id":"70c07120-0725-4a15-9e55-f24e626be5ec","reason":"canceled","price":"9147.53","remaining_size":"1.287"},{"type":"received","side":"buy","product_id":"BTC-USD","time":"2020-06-27T04:02:07.304860Z","sequence":14946197745,"order_id":"e482f43e-b10a-40ce-953f-4aa075398efb","order_type":"limit","size":"1.143","price":"9151.71","client_oid":"a6599707-7a2e-35e4-9613-4eebe0105b97"},{"type":"open","side":"buy","product_id":"BTC-USD","time":"2020-06-27T04:02:07.304860Z","sequence":14946197746,"price":"9151.71","order_id":"e482f43e-b10a-40ce-953f-4aa075398efb","remaining_size":"1.143"},{"type":"received","side":"sell","product_id":"ETH-USD","time":"2020-06-27T04:02:07.313819Z","sequence":9591230172,"order_id":"86fd4abc-c6fb-4fa5-8510-2e821e82fcd8","order_type":"limit","size":"26.93030243","price":"230.34","client_oid":"05bc8079-d54e-48a3-b546-e5e3a4e29c17"},{"type":"open","side":"sell","product_id":"ETH-USD","time":"2020-06-27T04:02:07.313819Z","sequence":9591230173,"price":"230.34","order_id":"86fd4abc-c6fb-4fa5-8510-2e821e82fcd8","remaining_size":"26.93030243"},{"type":"received","side":"buy","product_id":"BTC-USD","time":"2020-06-27T04:02:07.313952Z","sequence":14946197747,"order_id":"d9477b64-0089-4f44-8f68-9495af66de37","order_type":"limit","size":"1.285","price":"9147.01","client_oid":"7573974d-94a5-30b4-a220-a77dd75856eb"},{"type":"open","side":"buy","product_id":"BTC-USD","time":"2020-06-27T04:02:07.313952Z","sequence":14946197748,"price":"9147.01","order_id":"d9477b64-0089-4f44-8f68-9495af66de37","remaining_size":"1.285"},{"type":"done","side":"sell","product_id":"ETH-USD","time":"2020-06-27T04:02:07.318397Z","sequence":9591230174,"order_id":"112314ec-ec74-4e75-9c73-de6afc0ed60a","reason":"canceled","price":"229.95","remaining_size":"16.33863416"},{"type":"done","side":"sell","product_id":"ETH-USD","time":"2020-06-27T04:02:07.322884Z","sequence":9591230175,"order_id":"8e2e8cb8-a1bc-4d63-a561-6d1672932442","reason":"canceled","price":"230.03","remaining_size":"22.17359095"},{"type":"received","side":"sell","product_id":"BTC-USD","time":"2020-06-27T04:02:07.323902Z","sequence":14946197749,"order_id":"55ff372e-205b-48a7-8f9c-6a85ac70fc06","order_type":"limit","size":"1.166","price":"9177.27","client_oid":"2b50c44c-7a4a-3e9d-d3fe-12d25dfc0d4c"},{"type":"open","side":"sell","product_id":"BTC-USD","time":"2020-06-27T04:02:07.323902Z","sequence":14946197750,"price":"9177.27","order_id":"55ff372e-205b-48a7-8f9c-6a85ac70fc06","remaining_size":"1.166"},{"type":"received","side":"sell","product_id":"ETH-USD","time":"2020-06-27T04:02:07.328398Z","sequence":9591230176,"order_id":"f1c7be81-a339-4e27-8e0d-270d32f5c80a","order_type":"limit","size":"43.432","price":"229.6","client_oid":"92c6a628-af84-4933-a973-0c4dcb35c58e"},{"type":"open","side":"sell","product_id":"ETH-USD","time":"2020-06-27T04:02:07.328398Z","sequence":9591230177,"price":"229.6","order_id":"f1c7be81-a339-4e27-8e0d-270d32f5c80a","remaining_size":"43.432"},{"type":"done","side":"sell","product_id":"BTC-USD","time":"2020-06-27T04:02:07.329759Z","sequence":14946197751,"order_id":"fb7416b0-fbf7-4799-ab62-e99dc5d5493d","reason":"canceled","price":"9158.8","remaining_size":"0.03275815"},{"type":"done","side":"sell","product_id":"ETH-USD","time":"2020-06-27T04:02:07.332371Z","sequence":9591230178,"order_id":"da8cc565-9c83-4517-b2dd-3f24b6050c7c","reason":"canceled","price":"230.12","remaining_size":"17.90750108"},{"type":"received","side":"sell","product_id":"BTC-USD","time":"2020-06-27T04:02:07.333896Z","sequence":14946197752,"order_id":"ae16eeb4-1100-4975-8aba-e6aaa97762da","order_type":"limit","size":"1.24","price":"9181.97","client_oid":"b0a5ca8f-774d-3b43-95ea-062fe9b217f1"},{"type":"open","side":"sell","product_id":"BTC-USD","time":"2020-06-27T04:02:07.333896Z","sequence":14946197753,"price":"9181.97","order_id":"ae16eeb4-1100-4975-8aba-e6aaa97762da","remaining_size":"1.24"},{"type":"received","side":"sell","product_id":"ETH-USD","time":"2020-06-27T04:02:07.344620Z","sequence":9591230179,"order_id":"c28e6be8-8ef1-4423-a230-a27fee107f3b","order_type":"limit","size":"16.04680871","price":"230.46","client_oid":"d225fb95-70e5-4358-b566-622bdf7a7395"},{"type":"open","side":"sell","product_id":"ETH-USD","time":"2020-06-27T04:02:07.344620Z","sequence":9591230180,"price":"230.46","order_id":"c28e6be8-8ef1-4423-a230-a27fee107f3b","remaining_size":"16.04680871"},{"type":"received","side":"sell","product_id":"ETH-USD","time":"2020-06-27T04:02:07.344620Z","sequence":9591230181,"order_id":"c6a33cbd-f298-4753-bccb-512a8017ea06","order_type":"limit","size":"17.90750108","price":"229.95","client_oid":"d98404d7-632d-4d0d-a258-53f173c00e10"},{"type":"open","side":"sell","product_id":"ETH-USD","time":"2020-06-27T04:02:07.344620Z","sequence":9591230182,"price":"229.95","order_id":"c6a33cbd-f298-4753-bccb-512a8017ea06","remaining_size":"17.90750108"},{"type":"received","side":"sell","product_id":"ETH-USD","time":"2020-06-27T04:02:07.344620Z","sequence":9591230183,"order_id":"44af498c-f393-43f7-a087-96f07c09b133","order_type":"limit","size":"22.17359095","price":"229.83","client_oid":"1a63e9ab-f981-4214-bd29-8f16e81376ba"},{"type":"open","side":"sell","product_id":"ETH-USD","time":"2020-06-27T04:02:07.344620Z","sequence":9591230184,"price":"229.83","order_id":"44af498c-f393-43f7-a087-96f07c09b133","remaining_size":"22.17359095"},{"type":"received","side":"sell","product_id":"ETH-USD","time":"2020-06-27T04:02:07.344620Z","sequence":9591230185,"order_id":"2cf03b04-aa20-46ac-97c7-863c0e839af1","order_type":"limit","size":"16.33863416","price":"229.76","client_oid":"72bcc4bb-a8e9-4eae-9031-6e4faae9c8e4"},{"type":"open","side":"sell","product_id":"ETH-USD","time":"2020-06-27T04:02:07.344620Z","sequence":9591230186,"price":"229.76","order_id":"2cf03b04-aa20-46ac-97c7-863c0e839af1","remaining_size":"16.33863416"},{"type":"done","side":"sell","product_id":"BTC-USD","time":"2020-06-27T04:02:07.348545Z","sequence":14946197754,"order_id":"e031d324-2bd0-42cf-896a-328ef94500d7","reason":"canceled","price":"9159.05","remaining_size":"0.59767726"},{"type":"received","side":"sell","product_id":"BTC-USD","time":"2020-06-27T04:02:07.368958Z","sequence":14946197755,"order_id":"ff3889a3-547d-4e47-98ca-1abddede40f0","order_type":"limit","size":"0.59767726","price":"9159.74","client_oid":"28b87c1f-f92e-4d29-a7b9-8aee2090dd1d"},{"type":"open","side":"sell","product_id":"BTC-USD","time":"2020-06-27T04:02:07.368958Z","sequence":14946197756,"price":"9159.74","order_id":"ff3889a3-547d-4e47-98ca-1abddede40f0","remaining_size":"0.59767726"},{"type":"received","side":"sell","product_id":"BTC-USD","time":"2020-06-27T04:02:07.372887Z","sequence":14946197757,"order_id":"ac455dbf-0015-4159-9ddb-9cb3c0a02eea","order_type":"limit","size":"0.03275815","price":"9158.78","client_oid":"907b6ae6-bcbe-441a-b7bb-d932af6dd610"},{"type":"open","side":"sell","product_id":"BTC-USD","time":"2020-06-27T04:02:07.372887Z","sequence":14946197758,"price":"9158.78","order_id":"ac455dbf-0015-4159-9ddb-9cb3c0a02eea","remaining_size":"0.03275815"},{"type":"done","side":"sell","product_id":"BTC-USD","time":"2020-06-27T04:02:07.382844Z","sequence":14946197759,"order_id":"a2675055-fc5f-4977-849f-a66d87b9e68d","reason":"canceled","price":"9158.79","remaining_size":"0.7304137"},{"type":"done","side":"sell","product_id":"ETH-USD","time":"2020-06-27T04:02:07.390753Z","sequence":9591230187,"order_id":"5336e384-82d5-458f-a04f-7921b5a672ce","reason":"canceled","price":"230.43","remaining_size":"16.19573247"},{"type":"done","side":"buy","product_id":"ETH-USD","time":"2020-06-27T04:02:07.396349Z","sequence":9591230188,"order_id":"bf0de99e-15b2-4918-9863-22326fa7699d","reason":"canceled","price":"229.05","remaining_size":"19.55656714"},{"type":"received","side":"sell","product_id":"BTC-USD","time":"2020-06-27T04:02:07.401214Z","sequence":14946197760,"order_id":"234ff3b0-0eb9-4d00-bfb2-89acd5f477b2","order_type":"limit","size":"0.7304137","price":"9158.77","client_oid":"c3e9f285-2ce8-3aa8-159b-3d9932005000"},{"type":"open","side":"sell","product_id":"BTC-USD","time":"2020-06-27T04:02:07.401214Z","sequence":14946197761,"price":"9158.77","order_id":"234ff3b0-0eb9-4d00-bfb2-89acd5f477b2","remaining_size":"0.7304137"},{"type":"done","side":"buy","product_id":"ETH-USD","time":"2020-06-27T04:02:07.402950Z","sequence":9591230189,"order_id":"9c29befe-f353-4af7-8706-ffd8e23f3e46","reason":"canceled","price":"228.8","remaining_size":"20.28514544"},{"type":"done","side":"buy","product_id":"ETH-USD","time":"2020-06-27T04:02:07.408050Z","sequence":9591230190,"order_id":"9fc3d070-3040-4051-ada9-aa3334da6212","reason":"canceled","price":"228.54","remaining_size":"19.99677313"},{"type":"received","side":"sell","product_id":"BTC-USD","time":"2020-06-27T04:02:07.416539Z","sequence":14946197762,"order_id":"eee65faf-4678-45ae-8faa-a42ee43230dc","order_type":"limit","size":"0.1637","price":"9159.1","client_oid":"2000d461-1c8b-42c6-b623-592686e4b9b3"},{"type":"open","side":"sell","product_id":"BTC-USD","time":"2020-06-27T04:02:07.416539Z","sequence":14946197763,"price":"9159.1","order_id":"eee65faf-4678-45ae-8faa-a42ee43230dc","remaining_size":"0.1637"},{"type":"received","side":"buy","product_id":"ETH-USD","time":"2020-06-27T04:02:07.421974Z","sequence":9591230191,"order_id":"1c860973-bc59-44f1-a3bc-3a65ea3e9139","order_type":"limit","size":"16.78226374","price":"228.61","client_oid":"478a0d35-1223-48e6-8270-2caab862547f"},{"type":"open","side":"buy","product_id":"ETH-USD","time":"2020-06-27T04:02:07.421974Z","sequence":9591230192,"price":"228.61","order_id":"1c860973-bc59-44f1-a3bc-3a65ea3e9139","remaining_size":"16.78226374"},{"type":"received","side":"buy","product_id":"ETH-USD","time":"2020-06-27T04:02:07.421974Z","sequence":9591230193,"order_id":"88f540d4-8651-499e-b3e1-569273fa41c2","order_type":"limit","size":"19.99677313","price":"228.82","client_oid":"3247a663-362b-486b-a6df-489e95db6cd0"},{"type":"open","side":"buy","product_id":"ETH-USD","time":"2020-06-27T04:02:07.421974Z","sequence":9591230194,"price":"228.82","order_id":"88f540d4-8651-499e-b3e1-569273fa41c2","remaining_size":"19.99677313"},{"type":"received","side":"buy","product_id":"ETH-USD","time":"2020-06-27T04:02:07.421974Z","sequence":9591230195,"order_id":"dbd57ebd-468e-4b13-bc41-8343434aaf44","order_type":"limit","size":"20.28514544","price":"229","client_oid":"084ed61b-2ae3-43d5-9627-55e21551746a"},{"type":"open","side":"buy","product_id":"ETH-USD","time":"2020-06-27T04:02:07.421974Z","sequence":9591230196,"price":"229","order_id":"dbd57ebd-468e-4b13-bc41-8343434aaf44","remaining_size":"20.28514544"},{"type":"done","side":"sell","product_id":"BTC-USD","time":"2020-06-27T04:02:07.422631Z","sequence":14946197764,"order_id":"2c0b87f1-72b0-4234-9453-dc4778fae67a","reason":"canceled","price":"9216.9","remaining_size":"0.1"},{"type":"received","side":"buy","product_id":"ETH-USD","time":"2020-06-27T04:02:07.421974Z","sequence":9591230197,"order_id":"7d70bade-56b4-49c9-acf6-7982524cc15f","order_type":"limit","size":"19.55656714","price":"229.21","client_oid":"40bb30d8-83c9-4aa1-b7ed-b18adf9b20ef"},{"type":"open","side":"buy","product_id":"ETH-USD","time":"2020-06-27T04:02:07.421974Z","sequence":9591230198,"price":"229.21","order_id":"7d70bade-56b4-49c9-acf6-7982524cc15f","remaining_size":"19.55656714"},{"type":"received","side":"buy","product_id":"BTC-USD","time":"2020-06-27T04:02:07.426640Z","sequence":14946197765,"order_id":"47e86e4c-cee9-4b9c-b66d-5b04baddb306","order_type":"limit","size":"0.1637","price":"9155.36","client_oid":"20003816-6ce6-49cb-9c62-6b01a32bb8af"},{"type":"open","side":"buy","product_id":"BTC-USD","time":"2020-06-27T04:02:07.426640Z","sequence":14946197766,"price":"9155.36","order_id":"47e86e4c-cee9-4b9c-b66d-5b04baddb306","remaining_size":"0.1637"},{"type":"done","side":"sell","product_id":"BTC-USD","time":"2020-06-27T04:02:07.433206Z","sequence":14946197767,"order_id":"ac455dbf-0015-4159-9ddb-9cb3c0a02eea","reason":"canceled","price":"9158.78","remaining_size":"0.03275815"},{"type":"received","side":"sell","product_id":"BTC-USD","time":"2020-06-27T04:02:07.436625Z","sequence":14946197768,"order_id":"a219b39f-513a-47ff-a7b9-c945b10b8337","order_type":"limit","size":"0.8191","price":"9161.84","client_oid":"2002b442-d5f9-4621-99e7-fcddc52da8ed"},{"type":"open","side":"sell","product_id":"BTC-USD","time":"2020-06-27T04:02:07.436625Z","sequence":14946197769,"price":"9161.84","order_id":"a219b39f-513a-47ff-a7b9-c945b10b8337","remaining_size":"0.8191"},{"type":"received","side":"buy","product_id":"BTC-USD","time":"2020-06-27T04:02:07.447155Z","sequence":14946197770,"order_id":"8cc46811-f1c9-47bc-9362-971ae4f7e58b","order_type":"limit","size":"0.5461","price":"9153.95","client_oid":"2001b946-9529-4c69-9571-abb8d7568821"},{"type":"open","side":"buy","product_id":"BTC-USD","time":"2020-06-27T04:02:07.447155Z","sequence":14946197771,"price":"9153.95","order_id":"8cc46811-f1c9-47bc-9362-971ae4f7e58b","remaining_size":"0.5461"},{"type":"received","side":"buy","product_id":"BTC-USD","time":"2020-06-27T04:02:07.456783Z","sequence":14946197772,"order_id":"29161611-ca44-4526-8aec-e2846cb1e5af","order_type":"limit","size":"0.8192","price":"9152.11","client_oid":"2002f5a5-dd7b-46da-aa14-f39dcb0e4358"},{"type":"open","side":"buy","product_id":"BTC-USD","time":"2020-06-27T04:02:07.456783Z","sequence":14946197773,"price":"9152.11","order_id":"29161611-ca44-4526-8aec-e2846cb1e5af","remaining_size":"0.8192"},{"type":"done","side":"buy","product_id":"ETH-USD","time":"2020-06-27T04:02:07.457635Z","sequence":9591230199,"order_id":"4ac74bb3-270f-4228-bfba-3a85de6f5a71","reason":"canceled","price":"229.18","remaining_size":"16.66541968"},{"type":"received","side":"buy","product_id":"BTC-USD","time":"2020-06-27T04:02:07.465688Z","sequence":14946197774,"order_id":"131d3071-3263-405e-a31a-ca8b5f124607","order_type":"limit","size":"0.8192","price":"9152.11","client_oid":"20023faa-931d-49ed-ba27-b3b7869fc02b"},{"type":"open","side":"buy","product_id":"BTC-USD","time":"2020-06-27T04:02:07.465688Z","sequence":14946197775,"price":"9152.11","order_id":"131d3071-3263-405e-a31a-ca8b5f124607","remaining_size":"0.8192"},{"type":"done","side":"sell","product_id":"ETH-USD","time":"2020-06-27T04:02:07.469136Z","sequence":9591230200,"order_id":"86fd4abc-c6fb-4fa5-8510-2e821e82fcd8","reason":"canceled","price":"230.34","remaining_size":"26.93030243"},{"type":"done","side":"sell","product_id":"BTC-USD","time":"2020-06-27T04:02:07.471301Z","sequence":14946197776,"order_id":"544a63b5-0a73-431a-b7f7-2f503d398a19","reason":"canceled","price":"9158.81","remaining_size":"0.539"},{"type":"received","side":"sell","product_id":"BTC-USD","time":"2020-06-27T04:02:07.472079Z","sequence":14946197777,"order_id":"43446939-05b7-4ce9-a350-e51427e3e750","order_type":"limit","size":"0.03275815","price":"9158.76","client_oid":"907b6ae6-bcbe-441a-b7bb-d932af92d443"},{"type":"open","side":"sell","product_id":"BTC-USD","time":"2020-06-27T04:02:07.472079Z","sequence":14946197778,"price":"9158.76","order_id":"43446939-05b7-4ce9-a350-e51427e3e750","remaining_size":"0.03275815"},{"type":"done","side":"sell","product_id":"BTC-USD","time":"2020-06-27T04:02:07.473264Z","sequence":14946197779,"order_id":"234ff3b0-0eb9-4d00-bfb2-89acd5f477b2","reason":"canceled","price":"9158.77","remaining_size":"0.7304137"},{"type":"received","side":"sell","product_id":"BTC-USD","time":"2020-06-27T04:02:07.475646Z","sequence":14946197780,"order_id":"02f02426-c89b-4709-abc7-423d3ec91fdb","order_type":"limit","size":"0.543","price":"9158.77","client_oid":"b760318e-83f1-4973-aa70-30a722956a10"},{"type":"open","side":"sell","product_id":"BTC-USD","time":"2020-06-27T04:02:07.475646Z","sequence":14946197781,"price":"9158.77","order_id":"02f02426-c89b-4709-abc7-423d3ec91fdb","remaining_size":"0.543"},{"type":"received","side":"sell","product_id":"ETH-USD","time":"2020-06-27T04:02:07.478465Z","sequence":9591230201,"order_id":"80ed9d37-ca89-4c46-bba6-9345bb2f78c5","order_type":"limit","size":"26.93030243","price":"230.05","client_oid":"414084dd-fb2d-41fe-ac40-78bf6e1b83f3"},{"type":"open","side":"sell","product_id":"ETH-USD","time":"2020-06-27T04:02:07.478465Z","sequence":9591230202,"price":"230.05","order_id":"80ed9d37-ca89-4c46-bba6-9345bb2f78c5","remaining_size":"26.93030243"},{"type":"received","side":"buy","product_id":"ETH-USD","time":"2020-06-27T04:02:07.489845Z","sequence":9591230203,"order_id":"cdc78e0d-9d4f-448e-a2f0-5386fe8fdc61","order_type":"limit","size":"16.66557115","price":"229.17","client_oid":"2aedd7d9-4691-4993-a2f3-f43248d2479e"},{"type":"open","side":"buy","product_id":"ETH-USD","time":"2020-06-27T04:02:07.489845Z","sequence":9591230204,"price":"229.17","order_id":"cdc78e0d-9d4f-448e-a2f0-5386fe8fdc61","remaining_size":"16.66557115"},{"type":"received","side":"sell","product_id":"BTC-USD","time":"2020-06-27T04:02:07.493360Z","sequence":14946197782,"order_id":"592215d2-a827-4a26-871e-1bfe9c04f0b8","order_type":"limit","size":"0.7304137","price":"9158.75","client_oid":"fabc489b-5c92-cd63-a148-fd9932005000"},{"type":"open","side":"sell","product_id":"BTC-USD","time":"2020-06-27T04:02:07.493360Z","sequence":14946197783,"price":"9158.75","order_id":"592215d2-a827-4a26-871e-1bfe9c04f0b8","remaining_size":"0.7304137"},{"type":"received","side":"buy","product_id":"BTC-USD","time":"2020-06-27T04:02:07.494523Z","sequence":14946197784,"order_id":"0b1906cf-664b-45be-8059-71899759f52d","order_type":"limit","size":"0.01418505","price":"9155.36","client_oid":"eb711bd1-4779-47df-8e71-7f9cc8f112d2"},{"type":"open","side":"buy","product_id":"BTC-USD","time":"2020-06-27T04:02:07.494523Z","sequence":14946197785,"price":"9155.36","order_id":"0b1906cf-664b-45be-8059-71899759f52d","remaining_size":"0.01418505"},{"type":"received","side":"sell","product_id":"BTC-USD","time":"2020-06-27T04:02:07.523820Z","sequence":14946197786,"order_id":"26801f0a-0118-41f9-bc58-83e14132d965","order_type":"limit","size":"0.1","price":"9213.98","client_oid":"c38a8908-bcd1-425b-5ab9-3b656e592e31"},{"type":"open","side":"sell","product_id":"BTC-USD","time":"2020-06-27T04:02:07.523820Z","sequence":14946197787,"price":"9213.98","order_id":"26801f0a-0118-41f9-bc58-83e14132d965","remaining_size":"0.1"},{"type":"done","side":"sell","product_id":"BTC-USD","time":"2020-06-27T04:02:07.540287Z","sequence":14946197788,"order_id":"43446939-05b7-4ce9-a350-e51427e3e750","reason":"canceled","price":"9158.76","remaining_size":"0.03275815"},{"type":"done","side":"buy","product_id":"ETH-USD","time":"2020-06-27T04:02:07.550059Z","sequence":9591230205,"order_id":"47e29d8a-1261-4bf9-b5e5-0a3b29bf4a91","reason":"canceled","price":"228.79","remaining_size":"21.72135922"},{"type":"done","side":"buy","product_id":"ETH-USD","time":"2020-06-27T04:02:07.555328Z","sequence":9591230206,"order_id":"9a65f000-7309-4c59-b136-cc99a9d28b3f","reason":"canceled","price":"228.54","remaining_size":"17.59039854"},{"type":"received","side":"buy","product_id":"ETH-USD","time":"2020-06-27T04:02:07.566474Z","sequence":9591230207,"order_id":"5ec67ff4-4581-4bea-a8af-0aac4d268ac5","order_type":"limit","size":"21.60648456","price":"228.76","client_oid":"0a0a19f6-bc17-4919-b681-1d0eb4cfcaa6"},{"type":"open","side":"buy","product_id":"ETH-USD","time":"2020-06-27T04:02:07.566474Z","sequence":9591230208,"price":"228.76","order_id":"5ec67ff4-4581-4bea-a8af-0aac4d268ac5","remaining_size":"21.60648456"},{"type":"received","side":"buy","product_id":"ETH-USD","time":"2020-06-27T04:02:07.566474Z","sequence":9591230209,"order_id":"f9a9f7e0-f305-400c-8cfe-683b85e60769","order_type":"limit","size":"17.59039854","price":"228.85","client_oid":"677c7267-e3d0-454a-813a-84f09b118f82"},{"type":"open","side":"buy","product_id":"ETH-USD","time":"2020-06-27T04:02:07.566474Z","sequence":9591230210,"price":"228.85","order_id":"f9a9f7e0-f305-400c-8cfe-683b85e60769","remaining_size":"17.59039854"},{"type":"received","side":"buy","product_id":"ETH-USD","time":"2020-06-27T04:02:07.566474Z","sequence":9591230211,"order_id":"61d58485-982c-4552-9fa9-3996e655e91a","order_type":"limit","size":"21.72135922","price":"229.03","client_oid":"cf662c3c-b798-4f83-8306-99b485c7d3f5"},{"type":"open","side":"buy","product_id":"ETH-USD","time":"2020-06-27T04:02:07.566474Z","sequence":9591230212,"price":"229.03","order_id":"61d58485-982c-4552-9fa9-3996e655e91a","remaining_size":"21.72135922"},{"type":"done","side":"buy","product_id":"ETH-USD","time":"2020-06-27T04:02:07.571403Z","sequence":9591230213,"order_id":"7d70bade-56b4-49c9-acf6-7982524cc15f","reason":"canceled","price":"229.21","remaining_size":"19.55656714"},{"type":"done","side":"buy","product_id":"BTC-USD","time":"2020-06-27T04:02:07.578264Z","sequence":14946197789,"order_id":"a3718d5c-0714-415a-8e8c-65106c55f258","reason":"canceled","price":"9127.16","remaining_size":"0.01"},{"type":"received","side":"buy","product_id":"ETH-USD","time":"2020-06-27T04:02:07.581267Z","sequence":9591230214,"order_id":"860ad5b5-b72c-4e2c-a4b6-75921cd82d80","order_type":"limit","size":"19.55656714","price":"229.32","client_oid":"e26b36f0-7232-4e3e-a6be-a7005ed97159"},{"type":"open","side":"buy","product_id":"ETH-USD","time":"2020-06-27T04:02:07.581267Z","sequence":9591230215,"price":"229.32","order_id":"860ad5b5-b72c-4e2c-a4b6-75921cd82d80","remaining_size":"19.55656714"},{"type":"received","side":"buy","product_id":"BTC-USD","time":"2020-06-27T04:02:07.592930Z","sequence":14946197790,"order_id":"9b8cfb5e-d56a-4788-8670-10df2117ed17","order_type":"limit","size":"0.01","price":"9128.82","client_oid":"5c8f5857-035a-4103-bbd1-8e8a7c2bddb2"},{"type":"open","side":"buy","product_id":"BTC-USD","time":"2020-06-27T04:02:07.592930Z","sequence":14946197791,"price":"9128.82","order_id":"9b8cfb5e-d56a-4788-8670-10df2117ed17","remaining_size":"0.01"},{"type":"done","side":"sell","product_id":"BTC-USD","time":"2020-06-27T04:02:07.601594Z","sequence":14946197792,"order_id":"29c59516-e515-43ae-a515-c7ec518eb309","reason":"canceled","price":"9187.56","remaining_size":"0.04478512"},{"type":"done","side":"buy","product_id":"BTC-USD","time":"2020-06-27T04:02:07.610405Z","sequence":14946197793,"order_id":"9b8cfb5e-d56a-4788-8670-10df2117ed17","reason":"canceled","price":"9128.82","remaining_size":"0.01"},{"type":"received","side":"sell","product_id":"BTC-USD","time":"2020-06-27T04:02:07.610607Z","sequence":14946197794,"order_id":"0e7aac88-786e-46b0-96ac-0e92731fd1b7","order_type":"limit","size":"0.03275815","price":"9158.74","client_oid":"907b6ae6-bcbe-441a-b7bb-d932af100162"},{"type":"open","side":"sell","product_id":"BTC-USD","time":"2020-06-27T04:02:07.610607Z","sequence":14946197795,"price":"9158.74","order_id":"0e7aac88-786e-46b0-96ac-0e92731fd1b7","remaining_size":"0.03275815"},{"type":"received","side":"sell","product_id":"BTC-USD","time":"2020-06-27T04:02:07.613323Z","sequence":14946197796,"order_id":"6790fe3f-0cf4-4cee-8e5a-09d91bdd0b3d","order_type":"limit","size":"0.05441678","price":"9188.35","client_oid":"2060fc2b-092f-44b0-a2f5-3b8f10a510af"},{"type":"open","side":"sell","product_id":"BTC-USD","time":"2020-06-27T04:02:07.613323Z","sequence":14946197797,"price":"9188.35","order_id":"6790fe3f-0cf4-4cee-8e5a-09d91bdd0b3d","remaining_size":"0.05441678"},{"type":"done","side":"sell","product_id":"BTC-USD","time":"2020-06-27T04:02:07.614495Z","sequence":14946197798,"order_id":"31db7e68-f6ca-4e9c-b06f-c518fe2716b0","reason":"canceled","price":"9158.03","remaining_size":"0.05"},{"type":"done","side":"sell","product_id":"BTC-USD","time":"2020-06-27T04:02:07.623156Z","sequence":14946197799,"order_id":"592215d2-a827-4a26-871e-1bfe9c04f0b8","reason":"canceled","price":"9158.75","remaining_size":"0.7304137"},{"type":"received","side":"buy","product_id":"BTC-USD","time":"2020-06-27T04:02:07.633956Z","sequence":14946197800,"order_id":"092be90a-728b-42d0-8d0b-aeaef8f3ff7d","order_type":"limit","size":"0.01","price":"9123.86","client_oid":"19c3e797-3c1f-4786-a864-fcc1bc27b30e"},{"type":"open","side":"buy","product_id":"BTC-USD","time":"2020-06-27T04:02:07.633956Z","sequence":14946197801,"price":"9123.86","order_id":"092be90a-728b-42d0-8d0b-aeaef8f3ff7d","remaining_size":"0.01"},{"type":"received","side":"sell","product_id":"BTC-USD","time":"2020-06-27T04:02:07.643466Z","sequence":14946197802,"order_id":"afaae4d7-b064-47c7-bb5e-821caf12672b","order_type":"limit","size":"0.7304137","price":"9158.73","client_oid":"d6be1b95-64b5-8c37-ee75-df9932005000"},{"type":"open","side":"sell","product_id":"BTC-USD","time":"2020-06-27T04:02:07.643466Z","sequence":14946197803,"price":"9158.73","order_id":"afaae4d7-b064-47c7-bb5e-821caf12672b","remaining_size":"0.7304137"},{"type":"done","side":"sell","product_id":"BTC-USD","time":"2020-06-27T04:02:07.651555Z","sequence":14946197804,"order_id":"6790fe3f-0cf4-4cee-8e5a-09d91bdd0b3d","reason":"canceled","price":"9188.35","remaining_size":"0.05441678"},{"type":"received","side":"sell","product_id":"ETH-USD","time":"2020-06-27T04:02:07.658357Z","sequence":9591230216,"order_id":"bb2e7c8c-4dc2-4e1d-b305-f85552a73e2c","order_type":"limit","size":"16.38532478","price":"230.49","client_oid":"9da4a27f-78aa-4a70-8b31-73f526291716"},{"type":"open","side":"sell","product_id":"ETH-USD","time":"2020-06-27T04:02:07.658357Z","sequence":9591230217,"price":"230.49","order_id":"bb2e7c8c-4dc2-4e1d-b305-f85552a73e2c","remaining_size":"16.38532478"},{"type":"received","side":"sell","product_id":"BTC-USD","time":"2020-06-27T04:02:07.661602Z","sequence":14946197805,"order_id":"2909ebfb-0677-405c-936a-0ea1414e7b68","order_type":"limit","size":"0.03369366","price":"9187.56","client_oid":"1da41073-9378-4bea-bf17-7794752e79cb"},{"type":"open","side":"sell","product_id":"BTC-USD","time":"2020-06-27T04:02:07.661602Z","sequence":14946197806,"price":"9187.56","order_id":"2909ebfb-0677-405c-936a-0ea1414e7b68","remaining_size":"0.03369366"},{"type":"done","side":"sell","product_id":"BTC-USD","time":"2020-06-27T04:02:07.676604Z","sequence":14946197807,"order_id":"0e7aac88-786e-46b0-96ac-0e92731fd1b7","reason":"canceled","price":"9158.74","remaining_size":"0.03275815"},{"type":"received","side":"sell","product_id":"BTC-USD","time":"2020-06-27T04:02:07.677559Z","sequence":14946197808,"order_id":"88ff1eab-d65e-4a1d-9611-b0e0dcac8b78","order_type":"limit","size":"0.542","price":"9161.42","client_oid":"0d32513b-baea-4faa-86a2-3847c37fe597"},{"type":"open","side":"sell","product_id":"BTC-USD","time":"2020-06-27T04:02:07.677559Z","sequence":14946197809,"price":"9161.42","order_id":"88ff1eab-d65e-4a1d-9611-b0e0dcac8b78","remaining_size":"0.542"},{"type":"done","side":"sell","product_id":"BTC-USD","time":"2020-06-27T04:02:07.687586Z","sequence":14946197810,"order_id":"15df1bc6-1e71-4186-891e-63d5d25a304b","reason":"canceled","price":"9158.03","remaining_size":"1.85"},{"type":"done","side":"sell","product_id":"BTC-USD","time":"2020-06-27T04:02:07.698276Z","sequence":14946197811,"order_id":"afaae4d7-b064-47c7-bb5e-821caf12672b","reason":"canceled","price":"9158.73","remaining_size":"0.7304137"},{"type":"received","side":"buy","product_id":"BTC-USD","time":"2020-06-27T04:02:07.699863Z","sequence":14946197812,"order_id":"5edb9592-fcaf-4f3b-bac3-a201d9b313c7","order_type":"limit","size":"0.01701383","price":"9155.36","client_oid":"952c8adb-e1a0-4434-830e-ab991a742648"},{"type":"open","side":"buy","product_id":"BTC-USD","time":"2020-06-27T04:02:07.699863Z","sequence":14946197813,"price":"9155.36","order_id":"5edb9592-fcaf-4f3b-bac3-a201d9b313c7","remaining_size":"0.01701383"},{"type":"received","side":"sell","product_id":"BTC-USD","time":"2020-06-27T04:02:07.704281Z","sequence":14946197814,"order_id":"3321dffa-b467-4fc4-9062-71e7c8a4be1a","order_type":"limit","size":"0.05567108","price":"9158.33","client_oid":"c42d0f70-4b43-492e-9ca9-728c2a65bebb"},{"type":"open","side":"sell","product_id":"BTC-USD","time":"2020-06-27T04:02:07.704281Z","sequence":14946197815,"price":"9158.33","order_id":"3321dffa-b467-4fc4-9062-71e7c8a4be1a","remaining_size":"0.05567108"},{"type":"done","side":"sell","product_id":"BTC-USD","time":"2020-06-27T04:02:07.704453Z","sequence":14946197816,"order_id":"ff3889a3-547d-4e47-98ca-1abddede40f0","reason":"canceled","price":"9159.74","remaining_size":"0.59767726"},{"type":"done","side":"sell","product_id":"BTC-USD","time":"2020-06-27T04:02:07.709445Z","sequence":14946197817,"order_id":"776910d2-28ca-49f9-986d-a18650111c07","reason":"canceled","price":"9158.03","remaining_size":"0.05564746"},{"type":"received","side":"sell","product_id":"BTC-USD","time":"2020-06-27T04:02:07.717563Z","sequence":14946197818,"order_id":"e3184267-7a71-4ebe-944a-c32ad6376dd2","order_type":"limit","size":"0.7304137","price":"9158.76","client_oid":"c3e9f285-2ce8-3aa8-159b-b0a932005000"},{"type":"open","side":"sell","product_id":"BTC-USD","time":"2020-06-27T04:02:07.717563Z","sequence":14946197819,"price":"9158.76","order_id":"e3184267-7a71-4ebe-944a-c32ad6376dd2","remaining_size":"0.7304137"},{"type":"received","side":"sell","product_id":"BTC-USD","time":"2020-06-27T04:02:07.726436Z","sequence":14946197820,"order_id":"d5cbf1be-aa05-425a-85b9-f2226759cbeb","order_type":"limit","size":"0.03275815","price":"9158.72","client_oid":"907b6ae6-bcbe-441a-b7bb-d932afa7d24d"},{"type":"open","side":"sell","product_id":"BTC-USD","time":"2020-06-27T04:02:07.726436Z","sequence":14946197821,"price":"9158.72","order_id":"d5cbf1be-aa05-425a-85b9-f2226759cbeb","remaining_size":"0.03275815"},{"type":"received","side":"sell","product_id":"BTC-USD","time":"2020-06-27T04:02:07.726954Z","sequence":14946197822,"order_id":"15212375-61fc-40c8-a558-15536aced454","order_type":"limit","size":"0.59767726","price":"9159.93","client_oid":"d1e5a0a5-7f12-4013-86cc-f04fcf6b9a44"},{"type":"open","side":"sell","product_id":"BTC-USD","time":"2020-06-27T04:02:07.726954Z","sequence":14946197823,"price":"9159.93","order_id":"15212375-61fc-40c8-a558-15536aced454","remaining_size":"0.59767726"},{"type":"received","side":"sell","product_id":"BTC-USD","time":"2020-06-27T04:02:07.727483Z","sequence":14946197824,"order_id":"c90ca296-9fa5-43c5-ae91-4232f4585c96","order_type":"limit","size":"0.05567108","price":"9158.35","client_oid":"89a056ea-bd89-4629-879a-f6d5f7076a61"},{"type":"open","side":"sell","product_id":"BTC-USD","time":"2020-06-27T04:02:07.727483Z","sequence":14946197825,"price":"9158.35","order_id":"c90ca296-9fa5-43c5-ae91-4232f4585c96","remaining_size":"0.05567108"},{"type":"done","side":"buy","product_id":"ETH-USD","time":"2020-06-27T04:02:07.729988Z","sequence":9591230218,"order_id":"61d58485-982c-4552-9fa9-3996e655e91a","reason":"canceled","price":"229.03","remaining_size":"21.72135922"},{"type":"done","side":"sell","product_id":"BTC-USD","time":"2020-06-27T04:02:07.733475Z","sequence":14946197826,"order_id":"3321dffa-b467-4fc4-9062-71e7c8a4be1a","reason":"canceled","price":"9158.33","remaining_size":"0.05567108"},{"type":"received","side":"buy","product_id":"ETH-USD","time":"2020-06-27T04:02:07.742741Z","sequence":9591230219,"order_id":"846fa808-ad81-4ca8-87f6-2b8e0af7d7af","order_type":"limit","size":"21.2715522","price":"228.67","client_oid":"4dfa017f-990c-45db-bfa8-c63b7e75d185"},{"type":"open","side":"buy","product_id":"ETH-USD","time":"2020-06-27T04:02:07.742741Z","sequence":9591230220,"price":"228.67","order_id":"846fa808-ad81-4ca8-87f6-2b8e0af7d7af","remaining_size":"21.2715522"},{"type":"received","side":"buy","product_id":"ETH-USD","time":"2020-06-27T04:02:07.742741Z","sequence":9591230221,"order_id":"ad95ae71-a1a8-483c-bc58-ff0a58a884d8","order_type":"limit","size":"21.72135922","price":"229.23","client_oid":"a4ef4267-e717-4e6d-812a-5754421d5239"},{"type":"open","side":"buy","product_id":"ETH-USD","time":"2020-06-27T04:02:07.742741Z","sequence":9591230222,"price":"229.23","order_id":"ad95ae71-a1a8-483c-bc58-ff0a58a884d8","remaining_size":"21.72135922"},{"type":"done","side":"sell","product_id":"BTC-USD","time":"2020-06-27T04:02:07.759441Z","sequence":14946197827,"order_id":"d5cbf1be-aa05-425a-85b9-f2226759cbeb","reason":"canceled","price":"9158.72","remaining_size":"0.03275815"},{"type":"received","side":"sell","product_id":"BTC-USD","time":"2020-06-27T04:02:07.765426Z","sequence":14946197828,"order_id":"c18e856a-e4b0-4d17-84d9-dd3e3f06bfa0","order_type":"limit","size":"0.00362882","price":"8564.76","client_oid":"667dafc1-101f-40d7-9ef8-7fd22842eba2"},{"type":"match","side":"buy","product_id":"BTC-USD","time":"2020-06-27T04:02:07.765426Z","sequence":14946197829,"trade_id":95662174,"maker_order_id":"e72cdb6c-a63b-4891-8537-2c9f57f597d6","taker_order_id":"c18e856a-e4b0-4d17-84d9-dd3e3f06bfa0","size":"0.00362882","price":"9158.02"},{"type":"done","side":"sell","product_id":"BTC-USD","time":"2020-06-27T04:02:07.765426Z","sequence":14946197830,"order_id":"c18e856a-e4b0-4d17-84d9-dd3e3f06bfa0","reason":"filled","price":"8564.76","remaining_size":"0"},{"type":"received","side":"sell","product_id":"BTC-USD","time":"2020-06-27T04:02:07.777891Z","sequence":14946197831,"order_id":"65fcd87e-f60d-4d46-95f0-fe3e8f58dc2d","order_type":"limit","size":"1.85","price":"9158.03","client_oid":"20200627-0000-0000-0002-000000005418"},{"type":"open","side":"sell","product_id":"BTC-USD","time":"2020-06-27T04:02:07.777891Z","sequence":14946197832,"price":"9158.03","order_id":"65fcd87e-f60d-4d46-95f0-fe3e8f58dc2d","remaining_size":"1.85"},{"type":"received","side":"sell","product_id":"BTC-USD","time":"2020-06-27T04:02:07.794352Z","sequence":14946197833,"order_id":"d9da0554-60f9-41cb-954a-0c9ff7f780d3","order_type":"limit","size":"0.03275815","price":"9158.34","client_oid":"907b6ae6-bcbe-441a-b7bb-d932afc3c5b6"},{"type":"open","side":"sell","product_id":"BTC-USD","time":"2020-06-27T04:02:07.794352Z","sequence":14946197834,"price":"9158.34","order_id":"d9da0554-60f9-41cb-954a-0c9ff7f780d3","remaining_size":"0.03275815"},{"type":"heartbeat","last_trade_id":0,"product_id":"BTC-USD","sequence":14946197834,"time":"2020-06-27T04:02:07.832479Z"},{"type":"done","side":"sell","product_id":"BTC-USD","time":"2020-06-27T04:02:07.847794Z","sequence":14946197835,"order_id":"8eb208c6-b3e1-4621-84bb-0ffa0c35f649","reason":"canceled","price":"9160.89","remaining_size":"1.0969976"},{"type":"heartbeat","last_trade_id":0,"product_id":"ETH-USD","sequence":9591230222,"time":"2020-06-27T04:02:07.859207Z"},{"type":"received","side":"sell","product_id":"ETH-USD","time":"2020-06-27T04:02:07.861206Z","sequence":9591230223,"order_id":"7c0c25b2-eca6-44f9-b13e-37037b8a14aa","order_type":"limit","size":"8.70776","price":"229.79","client_oid":"d0e03b3a-bd5e-4e07-a67e-3c67c3430c59"},{"type":"open","side":"sell","product_id":"ETH-USD","time":"2020-06-27T04:02:07.861206Z","sequence":9591230224,"price":"229.79","order_id":"7c0c25b2-eca6-44f9-b13e-37037b8a14aa","remaining_size":"8.70776"},{"type":"done","side":"buy","product_id":"BTC-USD","time":"2020-06-27T04:02:07.873059Z","sequence":14946197836,"order_id":"092be90a-728b-42d0-8d0b-aeaef8f3ff7d","reason":"canceled","price":"9123.86","remaining_size":"0.01"},{"type":"received","side":"buy","product_id":"ETH-USD","time":"2020-06-27T04:02:07.883688Z","sequence":9591230225,"order_id":"465095fd-9d18-44dd-9cbb-dc602f1cda0c","order_type":"limit","size":"22.6766","price":"229.2","client_oid":""},{"type":"open","side":"buy","product_id":"ETH-USD","time":"2020-06-27T04:02:07.883688Z","sequence":9591230226,"price":"229.2","order_id":"465095fd-9d18-44dd-9cbb-dc602f1cda0c","remaining_size":"22.6766"},{"type":"received","side":"buy","product_id":"BTC-USD","time":"2020-06-27T04:02:07.885685Z","sequence":14946197837,"order_id":"c2e395fd-348c-4707-9f00-7b981e9bfb40","order_type":"limit","size":"0.01","price":"9128.82","client_oid":"a39c429f-706d-4b1a-b11f-5087a1940710"},{"type":"open","side":"buy","product_id":"BTC-USD","time":"2020-06-27T04:02:07.885685Z","sequence":14946197838,"price":"9128.82","order_id":"c2e395fd-348c-4707-9f00-7b981e9bfb40","remaining_size":"0.01"},{"type":"done","side":"sell","product_id":"BTC-USD","time":"2020-06-27T04:02:07.896440Z","sequence":14946197839,"order_id":"02f02426-c89b-4709-abc7-423d3ec91fdb","reason":"canceled","price":"9158.77","remaining_size":"0.543"},{"type":"done","side":"sell","product_id":"BTC-USD","time":"2020-06-27T04:02:07.902271Z","sequence":14946197840,"order_id":"88ff1eab-d65e-4a1d-9611-b0e0dcac8b78","reason":"canceled","price":"9161.42","remaining_size":"0.542"},{"type":"received","side":"sell","product_id":"BTC-USD","time":"2020-06-27T04:02:07.902824Z","sequence":14946197841,"order_id":"cb7d67fa-5dac-4165-ad96-cd08aaa95f3a","order_type":"limit","size":"0.539","price":"9159.05","client_oid":"c1e80f41-1df0-44d2-8b06-22395d38619c"},{"type":"open","side":"sell","product_id":"BTC-USD","time":"2020-06-27T04:02:07.902824Z","sequence":14946197842,"price":"9159.05","order_id":"cb7d67fa-5dac-4165-ad96-cd08aaa95f3a","remaining_size":"0.539"},{"type":"done","side":"sell","product_id":"BTC-USD","time":"2020-06-27T04:02:07.904253Z","sequence":14946197843,"order_id":"e3184267-7a71-4ebe-944a-c32ad6376dd2","reason":"canceled","price":"9158.76","remaining_size":"0.7304137"},{"type":"received","side":"sell","product_id":"BTC-USD","time":"2020-06-27T04:02:07.923881Z","sequence":14946197844,"order_id":"e7ed8314-b0b4-436e-abbd-1e61e3c2b020","order_type":"limit","size":"0.7304137","price":"9158.9","client_oid":"ff6a866b-ae61-5ad9-0414-52a932005000"},{"type":"open","side":"sell","product_id":"BTC-USD","time":"2020-06-27T04:02:07.923881Z","sequence":14946197845,"price":"9158.9","order_id":"e7ed8314-b0b4-436e-abbd-1e61e3c2b020","remaining_size":"0.7304137"},{"type":"done","side":"sell","product_id":"BTC-USD","time":"2020-06-27T04:02:07.925441Z","sequence":14946197846,"order_id":"5c6a871e-a5ad-44e3-a680-ceb41238b1ff","reason":"canceled","price":"9170.82","remaining_size":"1.06905367"},{"type":"done","side":"sell","product_id":"BTC-USD","time":"2020-06-27T04:02:07.929893Z","sequence":14946197847,"order_id":"dfd72f5c-a65e-4823-bbbe-1994aafeb30d","reason":"canceled","price":"9175.79","remaining_size":"1.14384454"},{"type":"done","side":"sell","product_id":"BTC-USD","time":"2020-06-27T04:02:07.933728Z","sequence":14946197848,"order_id":"5867403f-51ac-486b-9563-933a7f2b0aa5","reason":"canceled","price":"9188.1","remaining_size":"1.06790003"},{"type":"done","side":"sell","product_id":"BTC-USD","time":"2020-06-27T04:02:07.935879Z","sequence":14946197849,"order_id":"2909ebfb-0677-405c-936a-0ea1414e7b68","reason":"canceled","price":"9187.56","remaining_size":"0.03369366"},{"type":"done","side":"sell","product_id":"ETH-USD","time":"2020-06-27T04:02:07.938901Z","sequence":9591230227,"order_id":"e15e31c1-d2a9-4f62-bdec-ad04ebf17176","reason":"canceled","price":"229.7","remaining_size":"65.245"},{"type":"received","side":"sell","product_id":"ETH-USD","time":"2020-06-27T04:02:07.944032Z","sequence":9591230228,"order_id":"2c4c41af-22e9-4f53-a22e-fff8eee39f35","order_type":"limit","size":"65.301","price":"229.71","client_oid":"36e5f421-c789-42db-bf55-37d8c2ad3ca7"},{"type":"open","side":"sell","product_id":"ETH-USD","time":"2020-06-27T04:02:07.944032Z","sequence":9591230229,"price":"229.71","order_id":"2c4c41af-22e9-4f53-a22e-fff8eee39f35","remaining_size":"65.301"},{"type":"received","side":"sell","product_id":"BTC-USD","time":"2020-06-27T04:02:07.945761Z","sequence":14946197850,"order_id":"ecfca42b-4882-4ac8-b1cc-27d184737dab","order_type":"limit","size":"0.05441678","price":"9188.35","client_oid":"6d2d4e6d-f22f-4542-8598-39b68b478d4d"},{"type":"open","side":"sell","product_id":"BTC-USD","time":"2020-06-27T04:02:07.945761Z","sequence":14946197851,"price":"9188.35","order_id":"ecfca42b-4882-4ac8-b1cc-27d184737dab","remaining_size":"0.05441678"},{"type":"received","side":"sell","product_id":"BTC-USD","time":"2020-06-27T04:02:07.947458Z","sequence":14946197852,"order_id":"d52a2907-0b9d-43bd-956e-a22e47f25f0b","order_type":"limit","size":"1.00865284","price":"9186.24","client_oid":"1fbd4305-b277-4b09-8127-463bed2c4553"},{"type":"open","side":"sell","product_id":"BTC-USD","time":"2020-06-27T04:02:07.947458Z","sequence":14946197853,"price":"9186.24","order_id":"d52a2907-0b9d-43bd-956e-a22e47f25f0b","remaining_size":"1.00865284"},{"type":"received","side":"sell","product_id":"BTC-USD","time":"2020-06-27T04:02:07.947458Z","sequence":14946197854,"order_id":"02b8c95d-fc94-4345-a351-bc0b7e85aa57","order_type":"limit","size":"1.06790003","price":"9180.37","client_oid":"d983f6f9-2c55-4f04-b9d6-42d81649484d"},{"type":"open","side":"sell","product_id":"BTC-USD","time":"2020-06-27T04:02:07.947458Z","sequence":14946197855,"price":"9180.37","order_id":"02b8c95d-fc94-4345-a351-bc0b7e85aa57","remaining_size":"1.06790003"},{"type":"received","side":"sell","product_id":"BTC-USD","time":"2020-06-27T04:02:07.947458Z","sequence":14946197856,"order_id":"8a7c9a2a-14cd-4680-bc93-e632d9531598","order_type":"limit","size":"1.14384454","price":"9170.7","client_oid":"81ce9f29-1784-4534-a5d1-d16a3fc8e2f4"},{"type":"open","side":"sell","product_id":"BTC-USD","time":"2020-06-27T04:02:07.947458Z","sequence":14946197857,"price":"9170.7","order_id":"8a7c9a2a-14cd-4680-bc93-e632d9531598","remaining_size":"1.14384454"},{"type":"received","side":"sell","product_id":"BTC-USD","time":"2020-06-27T04:02:07.947458Z","sequence":14946197858,"order_id":"107bd496-ff6d-4253-9acd-3dcc50ef9f39","order_type":"limit","size":"1.06905367","price":"9167.59","client_oid":"b681af2c-0710-406f-ae0f-c761e554901d"},{"type":"open","side":"sell","product_id":"BTC-USD","time":"2020-06-27T04:02:07.947458Z","sequence":14946197859,"price":"9167.59","order_id":"107bd496-ff6d-4253-9acd-3dcc50ef9f39","remaining_size":"1.06905367"},{"type":"received","side":"sell","product_id":"ETH-USD","time":"2020-06-27T04:02:07.950038Z","sequence":9591230230,"order_id":"ea80c47a-31fd-4ea0-92bd-ae148909722e","order_type":"limit","size":"23.28875237","price":"229.68","client_oid":"ff6a866b-ae61-5ad9-0414-b2a932000100"},{"type":"open","side":"sell","product_id":"ETH-USD","time":"2020-06-27T04:02:07.950038Z","sequence":9591230231,"price":"229.68","order_id":"ea80c47a-31fd-4ea0-92bd-ae148909722e","remaining_size":"23.28875237"},{"type":"done","side":"sell","product_id":"BTC-USD","time":"2020-06-27T04:02:07.955017Z","sequence":14946197860,"order_id":"d297b085-1748-49c8-a8f1-2f24c1e7fcb2","reason":"canceled","price":"9175.79","remaining_size":"1.37039955"},{"type":"done","side":"sell","product_id":"BTC-USD","time":"2020-06-27T04:02:07.958443Z","sequence":14946197861,"order_id":"4e4d860b-d701-4831-ab9e-87c2aff35262","reason":"canceled","price":"9188.76","remaining_size":"1.10660796"},{"type":"done","side":"buy","product_id":"BTC-USD","time":"2020-06-27T04:02:07.966818Z","sequence":14946197862,"order_id":"e72cdb6c-a63b-4891-8537-2c9f57f597d6","reason":"canceled","price":"9158.02","remaining_size":"0.35637118"},{"type":"done","side":"sell","product_id":"BTC-USD","time":"2020-06-27T04:02:07.973935Z","sequence":14946197863,"order_id":"5956c6ff-eeb4-4929-b5f5-df34648515bc","reason":"canceled","price":"9158.03","remaining_size":"0.2072097"},{"type":"done","side":"sell","product_id":"BTC-USD","time":"2020-06-27T04:02:07.974716Z","sequence":14946197864,"order_id":"e7ed8314-b0b4-436e-abbd-1e61e3c2b020","reason":"canceled","price":"9158.9","remaining_size":"0.7304137"},{"type":"done","side":"sell","product_id":"BTC-USD","time":"2020-06-27T04:02:07.974729Z","sequence":14946197865,"order_id":"bcd66577-7816-4f1b-bc2a-3d2153aa6f12","reason":"canceled","price":"9158.03","remaining_size":"0.16849806"},{"type":"done","side":"buy","product_id":"BTC-USD","time":"2020-06-27T04:02:07.976142Z","sequence":14946197866,"order_id":"5ba433c5-e302-47ae-8ffe-25241b893af7","reason":"canceled","price":"9153.06","remaining_size":"0.47149726"},{"type":"done","side":"buy","product_id":"BTC-USD","time":"2020-06-27T04:02:07.976441Z","sequence":14946197867,"order_id":"0b1906cf-664b-45be-8059-71899759f52d","reason":"canceled","price":"9155.36","remaining_size":"0.01418505"},{"type":"done","side":"sell","product_id":"BTC-USD","time":"2020-06-27T04:02:07.978452Z","sequence":14946197868,"order_id":"cad5bf2a-ab68-43e0-8eda-e566f5a36c5e","reason":"canceled","price":"9158.03","remaining_size":"0.1166848"},{"type":"done","side":"buy","product_id":"BTC-USD","time":"2020-06-27T04:02:07.979485Z","sequence":14946197869,"order_id":"f1203280-0455-4691-915d-8a1813f494da","reason":"canceled","price":"9139.7","remaining_size":"0.5"},{"type":"done","side":"buy","product_id":"BTC-USD","time":"2020-06-27T04:02:07.979847Z","sequence":14946197870,"order_id":"0f1a7e38-ff0a-470b-ae7c-aeebe6dadf03","reason":"canceled","price":"9155.36","remaining_size":"0.01735689"},{"type":"done","side":"buy","product_id":"BTC-USD","time":"2020-06-27T04:02:07.981540Z","sequence":14946197871,"order_id":"5edb9592-fcaf-4f3b-bac3-a201d9b313c7","reason":"canceled","price":"9155.36","remaining_size":"0.01701383"},{"type":"received","side":"sell","product_id":"BTC-USD","time":"2020-06-27T04:02:07.981589Z","sequence":14946197872,"order_id":"97834d72-c707-491b-a280-822a4010facd","order_type":"limit","size":"0.05567108","price":"9158.02","client_oid":"94e98741-7038-4e43-86f9-892a653db718"},{"type":"open","side":"sell","product_id":"BTC-USD","time":"2020-06-27T04:02:07.981589Z","sequence":14946197873,"price":"9158.02","order_id":"97834d72-c707-491b-a280-822a4010facd","remaining_size":"0.05567108"},{"type":"received","side":"sell","product_id":"BTC-USD","time":"2020-06-27T04:02:07.982470Z","sequence":14946197874,"order_id":"f9d5f09c-5670-4de3-a1fe-5b3c864fba87","order_type":"limit","size":"0.05","price":"9158.01","client_oid":"6be01787-3157-4da3-882c-1ba0ec31482c"},{"type":"open","side":"sell","product_id":"BTC-USD","time":"2020-06-27T04:02:07.982470Z","sequence":14946197875,"price":"9158.01","order_id":"f9d5f09c-5670-4de3-a1fe-5b3c864fba87","remaining_size":"0.05"},{"type":"done","side":"sell","product_id":"BTC-USD","time":"2020-06-27T04:02:07.985865Z","sequence":14946197876,"order_id":"f5f814de-b382-42be-8380-f81d8f8ae183","reason":"canceled","price":"9193.49","remaining_size":"0.01"},{"type":"done","side":"sell","product_id":"BTC-USD","time":"2020-06-27T04:02:07.986757Z","sequence":14946197877,"order_id":"c90ca296-9fa5-43c5-ae91-4232f4585c96","reason":"canceled","price":"9158.35","remaining_size":"0.05567108"},{"type":"done","side":"sell","product_id":"BTC-USD","time":"2020-06-27T04:02:07.987511Z","sequence":14946197878,"order_id":"cf7a085d-a95a-4bf5-b360-a529deedfeec","reason":"canceled","price":"9158.03","remaining_size":"0.09637381"},{"type":"received","side":"buy","product_id":"BTC-USD","time":"2020-06-27T04:02:07.988462Z","sequence":14946197879,"order_id":"5229d439-3b1e-4b43-b0d2-6d9d2dfde9c2","order_type":"limit","size":"0.5","price":"9139.68","client_oid":"c0c7c8ba-0519-4887-b2e7-32a26b30593b"},{"type":"open","side":"buy","product_id":"BTC-USD","time":"2020-06-27T04:02:07.988462Z","sequence":14946197880,"price":"9139.68","order_id":"5229d439-3b1e-4b43-b0d2-6d9d2dfde9c2","remaining_size":"0.5"},{"type":"done","side":"sell","product_id":"BTC-USD","time":"2020-06-27T04:02:07.989678Z","sequence":14946197881,"order_id":"ecfca42b-4882-4ac8-b1cc-27d184737dab","reason":"canceled","price":"9188.35","remaining_size":"0.05441678"},{"type":"received","side":"sell","product_id":"BTC-USD","time":"2020-06-27T04:02:07.992283Z","sequence":14946197882,"order_id":"448b092b-a432-4c97-a993-0e54a6e89f12","order_type":"limit","size":"0.11444618","price":"9158.01","client_oid":"b0b3ae0d-8178-43ba-9223-223f00a13aaa"},{"type":"open","side":"sell","product_id":"BTC-USD","time":"2020-06-27T04:02:07.992283Z","sequence":14946197883,"price":"9158.01","order_id":"448b092b-a432-4c97-a993-0e54a6e89f12","remaining_size":"0.11444618"},{"type":"received","side":"sell","product_id":"BTC-USD","time":"2020-06-27T04:02:07.993619Z","sequence":14946197884,"order_id":"d5a77156-9fae-4640-902b-fb719c0c76f8","order_type":"limit","size":"0.00450133","price":"9158.01","client_oid":"00000000-0000-0000-0005-a8fe1f068223"},{"type":"open","side":"sell","product_id":"BTC-USD","time":"2020-06-27T04:02:07.993619Z","sequence":14946197885,"price":"9158.01","order_id":"d5a77156-9fae-4640-902b-fb719c0c76f8","remaining_size":"0.00450133"},{"type":"received","side":"sell","product_id":"BTC-USD","time":"2020-06-27T04:02:07.993676Z","sequence":14946197886,"order_id":"69241467-7dba-485d-b8e0-f4c1070a8040","order_type":"limit","size":"1.85","price":"9158.01","client_oid":"20200627-0000-0000-0003-000000005451"},{"type":"open","side":"sell","product_id":"BTC-USD","time":"2020-06-27T04:02:07.993676Z","sequence":14946197887,"price":"9158.01","order_id":"69241467-7dba-485d-b8e0-f4c1070a8040","remaining_size":"1.85"},{"type":"done","side":"sell","product_id":"BTC-USD","time":"2020-06-27T04:02:07.994177Z","sequence":14946197888,"order_id":"f9d5f09c-5670-4de3-a1fe-5b3c864fba87","reason":"canceled","price":"9158.01","remaining_size":"0.05"},{"type":"done","side":"sell","product_id":"BTC-USD","time":"2020-06-27T04:02:07.994582Z","sequence":14946197889,"order_id":"ec9499d0-1aa8-4a11-b77f-ecdadd2437f8","reason":"canceled","price":"9158.03","remaining_size":"0.2"},{"type":"received","side":"sell","product_id":"BTC-USD","time":"2020-06-27T04:02:07.995205Z","sequence":14946197890,"order_id":"fa576986-b712-4977-8272-b07a6db3b2dc","order_type":"limit","size":"0.01","price":"9194.24","client_oid":"d2b539d1-0c35-4a5b-9846-ad645c62bdad"},{"type":"open","side":"sell","product_id":"BTC-USD","time":"2020-06-27T04:02:07.995205Z","sequence":14946197891,"price":"9194.24","order_id":"fa576986-b712-4977-8272-b07a6db3b2dc","remaining_size":"0.01"},{"type":"received","side":"sell","product_id":"BTC-USD","time":"2020-06-27T04:02:07.996190Z","sequence":14946197892,"order_id":"9e89dab8-5dd8-428e-8ef2-84874358ae6a","order_type":"limit","size":"0.7304137","price":"9158.01","client_oid":"c3e9f285-2ce8-3aa8-159b-33a932005000"},{"type":"open","side":"sell","product_id":"BTC-USD","time":"2020-06-27T04:02:07.996190Z","sequence":14946197893,"price":"9158.01","order_id":"9e89dab8-5dd8-428e-8ef2-84874358ae6a","remaining_size":"0.7304137"},{"type":"received","side":"sell","product_id":"BTC-USD","time":"2020-06-27T04:02:07.997484Z","sequence":14946197894,"order_id":"0a936926-3241-42f6-9ff2-77488a2aa608","order_type":"limit","size":"0.05567108","price":"9158.01","client_oid":"74969a63-83a1-410d-864d-59be094eb240"},{"type":"open","side":"sell","product_id":"BTC-USD","time":"2020-06-27T04:02:07.997484Z","sequence":14946197895,"price":"9158.01","order_id":"0a936926-3241-42f6-9ff2-77488a2aa608","remaining_size":"0.05567108"},{"type":"received","side":"sell","product_id":"BTC-USD","time":"2020-06-27T04:02:07.998970Z","sequence":14946197896,"order_id":"a6dfccbd-e758-4c9f-ba4d-cf587025836a","order_type":"limit","size":"0.19518344","price":"9158.01","client_oid":"2051529f-e820-4af8-a39c-14ba8b455d06"},{"type":"open","side":"sell","product_id":"BTC-USD","time":"2020-06-27T04:02:07.998970Z","sequence":14946197897,"price":"9158.01","order_id":"a6dfccbd-e758-4c9f-ba4d-cf587025836a","remaining_size":"0.19518344"},{"type":"done","side":"sell","product_id":"BTC-USD","time":"2020-06-27T04:02:08.000033Z","sequence":14946197898,"order_id":"15212375-61fc-40c8-a558-15536aced454","reason":"canceled","price":"9159.93","remaining_size":"0.59767726"},{"type":"received","side":"sell","product_id":"BTC-USD","time":"2020-06-27T04:02:08.000866Z","sequence":14946197899,"order_id":"d1bc3e9c-a6e4-4a96-91b2-eaec0ed919b5","order_type":"limit","size":"0.04478512","price":"9187.56","client_oid":"798ed3d9-d4ba-4751-a881-7d7e6692f939"},{"type":"open","side":"sell","product_id":"BTC-USD","time":"2020-06-27T04:02:08.000866Z","sequence":14946197900,"price":"9187.56","order_id":"d1bc3e9c-a6e4-4a96-91b2-eaec0ed919b5","remaining_size":"0.04478512"},{"type":"received","side":"sell","product_id":"BTC-USD","time":"2020-06-27T04:02:08.002331Z","sequence":14946197901,"order_id":"73ed7eee-bfbb-4c8b-91f1-3832c89cf9c7","order_type":"limit","size":"0.08853624","price":"9158.01","client_oid":"21757cfe-a204-4941-a483-a2a7a70aab63"},{"type":"open","side":"sell","product_id":"BTC-USD","time":"2020-06-27T04:02:08.002331Z","sequence":14946197902,"price":"9158.01","order_id":"73ed7eee-bfbb-4c8b-91f1-3832c89cf9c7","remaining_size":"0.08853624"},{"type":"done","side":"sell","product_id":"BTC-USD","time":"2020-06-27T04:02:08.006211Z","sequence":14946197903,"order_id":"fa576986-b712-4977-8272-b07a6db3b2dc","reason":"canceled","price":"9194.24","remaining_size":"0.01"},{"type":"received","side":"sell","product_id":"BTC-USD","time":"2020-06-27T04:02:08.007074Z","sequence":14946197904,"order_id":"f921f549-4df4-40cf-a53e-85dfd147a117","order_type":"limit","size":"0.10183414","price":"9158.01","client_oid":"c6bbf374-3940-46b5-ba1f-f174ee69aa2a"},{"type":"open","side":"sell","product_id":"BTC-USD","time":"2020-06-27T04:02:08.007074Z","sequence":14946197905,"price":"9158.01","order_id":"f921f549-4df4-40cf-a53e-85dfd147a117","remaining_size":"0.10183414"},{"type":"received","side":"sell","product_id":"BTC-USD","time":"2020-06-27T04:02:08.011148Z","sequence":14946197906,"order_id":"057820a3-35ed-435a-b23c-ca0122f305f0","order_type":"limit","size":"0.2","price":"9158.01","client_oid":"20202020-2020-2020-ab9c-4c895776df37"},{"type":"open","side":"sell","product_id":"BTC-USD","time":"2020-06-27T04:02:08.011148Z","sequence":14946197907,"price":"9158.01","order_id":"057820a3-35ed-435a-b23c-ca0122f305f0","remaining_size":"0.2"},{"type":"received","side":"sell","product_id":"BTC-USD","time":"2020-06-27T04:02:08.019150Z","sequence":14946197908,"order_id":"f99c9a84-c243-4aaa-b518-0288742487cd","order_type":"limit","size":"0.01","price":"9193.87","client_oid":"6d16c616-f51f-4d81-90ed-a618ee0dd38d"},{"type":"open","side":"sell","product_id":"BTC-USD","time":"2020-06-27T04:02:08.019150Z","sequence":14946197909,"price":"9193.87","order_id":"f99c9a84-c243-4aaa-b518-0288742487cd","remaining_size":"0.01"},{"type":"done","side":"buy","product_id":"ETH-USD","time":"2020-06-27T04:02:08.020947Z","sequence":9591230232,"order_id":"cdc78e0d-9d4f-448e-a2f0-5386fe8fdc61","reason":"canceled","price":"229.17","remaining_size":"16.66557115"},{"type":"done","side":"sell","product_id":"BTC-USD","time":"2020-06-27T04:02:08.028482Z","sequence":14946197910,"order_id":"d9da0554-60f9-41cb-954a-0c9ff7f780d3","reason":"canceled","price":"9158.34","remaining_size":"0.03275815"},{"type":"received","side":"buy","product_id":"BTC-USD","time":"2020-06-27T04:02:08.031299Z","sequence":14946197911,"order_id":"e4c6ae51-d41a-4ac8-892b-71757183953c","order_type":"limit","size":"0.47671878","price":"9152.69","client_oid":"3f200367-74f5-4a3e-8843-90b315ed1d6a"},{"type":"open","side":"buy","product_id":"BTC-USD","time":"2020-06-27T04:02:08.031299Z","sequence":14946197912,"price":"9152.69","order_id":"e4c6ae51-d41a-4ac8-892b-71757183953c","remaining_size":"0.47671878"},{"type":"received","side":"sell","product_id":"BTC-USD","time":"2020-06-27T04:02:08.040844Z","sequence":14946197913,"order_id":"e8875af7-12bb-4c13-810e-490e52717542","order_type":"limit","size":"0.59767726","price":"9159.29","client_oid":"4ee6f0ec-5eb4-488b-8291-325d690d9979"},{"type":"open","side":"sell","product_id":"BTC-USD","time":"2020-06-27T04:02:08.040844Z","sequence":14946197914,"price":"9159.29","order_id":"e8875af7-12bb-4c13-810e-490e52717542","remaining_size":"0.59767726"},{"type":"done","side":"sell","product_id":"BTC-USD","time":"2020-06-27T04:02:08.055254Z","sequence":14946197915,"order_id":"2b4d2708-8218-4caa-b11f-069e583f71b2","reason":"canceled","price":"9179.28","remaining_size":"1.03602174"},{"type":"received","side":"buy","product_id":"ETH-USD","time":"2020-06-27T04:02:08.056258Z","sequence":9591230233,"order_id":"5a55fd61-01fd-4fc2-a24c-6ab319b5efd7","order_type":"limit","size":"16.66553228","price":"229.17","client_oid":"c28261a4-ff97-4268-8f0b-f89c2a589d64"},{"type":"open","side":"buy","product_id":"ETH-USD","time":"2020-06-27T04:02:08.056258Z","sequence":9591230234,"price":"229.17","order_id":"5a55fd61-01fd-4fc2-a24c-6ab319b5efd7","remaining_size":"16.66553228"},{"type":"received","side":"sell","product_id":"BTC-USD","time":"2020-06-27T04:02:08.088228Z","sequence":14946197916,"order_id":"fd854611-873c-457c-a969-c0ed5ff41a32","order_type":"limit","size":"0.03275821","price":"9158.02","client_oid":"907b6ae6-bcbe-441a-b7bb-d932afbb2adf"},{"type":"open","side":"sell","product_id":"BTC-USD","time":"2020-06-27T04:02:08.088228Z","sequence":14946197917,"price":"9158.02","order_id":"fd854611-873c-457c-a969-c0ed5ff41a32","remaining_size":"0.03275821"},{"type":"done","side":"sell","product_id":"BTC-USD","time":"2020-06-27T04:02:08.091813Z","sequence":14946197918,"order_id":"42c07292-5ef4-40b5-8e39-bb760d0e9d93","reason":"canceled","price":"9176.35","remaining_size":"0.5"},{"type":"received","side":"sell","product_id":"BTC-USD","time":"2020-06-27T04:02:08.099589Z","sequence":14946197919,"order_id":"7cbde9b7-cdcc-44aa-b80c-5872bccd39c1","order_type":"limit","size":"0.5","price":"9176.33","client_oid":"2250d054-3379-40b4-957b-da282d729a2a"},{"type":"open","side":"sell","product_id":"BTC-USD","time":"2020-06-27T04:02:08.099589Z","sequence":14946197920,"price":"9176.33","order_id":"7cbde9b7-cdcc-44aa-b80c-5872bccd39c1","remaining_size":"0.5"},{"type":"done","side":"buy","product_id":"BTC-USD","time":"2020-06-27T04:02:08.130862Z","sequence":14946197921,"order_id":"5ad63cfc-57aa-435e-9259-13caa68e8595","reason":"canceled","price":"9150.67","remaining_size":"0.5"},{"type":"done","side":"buy","product_id":"BTC-USD","time":"2020-06-27T04:02:08.134695Z","sequence":14946197922,"order_id":"b38c9f5b-2ce4-4ef1-8816-71c7f8794251","reason":"canceled","price":"9155.36","remaining_size":"0.3"},{"type":"received","side":"sell","product_id":"BTC-USD","time":"2020-06-27T04:02:08.137737Z","sequence":14946197923,"order_id":"c757e166-accd-490a-b7db-3af67812c2d9","order_type":"limit","size":"1.25316497","price":"9181.47","client_oid":"ad427e08-49f3-4c46-9d95-07ae3705d6dd"},{"type":"open","side":"sell","product_id":"BTC-USD","time":"2020-06-27T04:02:08.137737Z","sequence":14946197924,"price":"9181.47","order_id":"c757e166-accd-490a-b7db-3af67812c2d9","remaining_size":"1.25316497"},{"type":"received","side":"sell","product_id":"BTC-USD","time":"2020-06-27T04:02:08.137737Z","sequence":14946197925,"order_id":"246a62e4-779a-43f1-bcad-60315bd48b6e","order_type":"limit","size":"1.03602174","price":"9173.29","client_oid":"0bf87648-abd6-44e0-aefc-bfa3cd899c51"},{"type":"open","side":"sell","product_id":"BTC-USD","time":"2020-06-27T04:02:08.137737Z","sequence":14946197926,"price":"9173.29","order_id":"246a62e4-779a-43f1-bcad-60315bd48b6e","remaining_size":"1.03602174"},{"type":"received","side":"buy","product_id":"BTC-USD","time":"2020-06-27T04:02:08.149493Z","sequence":14946197927,"order_id":"9d11d2de-7ea4-41c6-bffc-604bdd65c9ee","order_type":"limit","size":"0.3","price":"9152.45","client_oid":"f7a765f8-b82a-11ea-a5d7-0a070dc90c3f"},{"type":"open","side":"buy","product_id":"BTC-USD","time":"2020-06-27T04:02:08.149493Z","sequence":14946197928,"price":"9152.45","order_id":"9d11d2de-7ea4-41c6-bffc-604bdd65c9ee","remaining_size":"0.3"},{"type":"done","side":"sell","product_id":"BTC-USD","time":"2020-06-27T04:02:08.169751Z","sequence":14946197929,"order_id":"91a3890f-5e88-4a72-b71b-e175c222d8d3","reason":"canceled","price":"9160.7","remaining_size":"0.49363717"},{"type":"received","side":"sell","product_id":"BTC-USD","time":"2020-06-27T04:02:08.209567Z","sequence":14946197930,"order_id":"a0ca470d-142e-4e62-8753-c7caf9c7b88f","order_type":"limit","size":"0.49366414","price":"9161.02","client_oid":"643451ab-85ba-4ce1-9740-ca6213fed054"},{"type":"open","side":"sell","product_id":"BTC-USD","time":"2020-06-27T04:02:08.209567Z","sequence":14946197931,"price":"9161.02","order_id":"a0ca470d-142e-4e62-8753-c7caf9c7b88f","remaining_size":"0.49366414"},{"type":"received","side":"sell","product_id":"BTC-USD","time":"2020-06-27T04:02:08.219445Z","sequence":14946197932,"order_id":"91c91456-a8d9-472f-808d-895c15f9d60f","order_type":"limit","size":"1.18483974","price":"9186.22","client_oid":"594775d1-d411-44e2-81df-a91c9bd6c746"},{"type":"open","side":"sell","product_id":"BTC-USD","time":"2020-06-27T04:02:08.219445Z","sequence":14946197933,"price":"9186.22","order_id":"91c91456-a8d9-472f-808d-895c15f9d60f","remaining_size":"1.18483974"},{"type":"done","side":"sell","product_id":"BTC-USD","time":"2020-06-27T04:02:08.255395Z","sequence":14946197934,"order_id":"cc25b7a4-2faf-4df2-8520-7aa9e631ec72","reason":"canceled","price":"9203.94","remaining_size":"0.05432456"},{"type":"done","side":"buy","product_id":"BTC-USD","time":"2020-06-27T04:02:08.259568Z","sequence":14946197935,"order_id":"c1069206-740f-419c-b236-5e7cdedf7c60","reason":"canceled","price":"9106.53","remaining_size":"0.05490561"},{"type":"received","side":"sell","product_id":"BTC-USD","time":"2020-06-27T04:02:08.270409Z","sequence":14946197936,"order_id":"a94fa570-ff0d-4a6c-9fe7-455c0cd75748","order_type":"limit","size":"0.05423175","price":"9219.69","client_oid":"80464e19-e966-4d2f-98de-899b3ebe886b"},{"type":"open","side":"sell","product_id":"BTC-USD","time":"2020-06-27T04:02:08.270409Z","sequence":14946197937,"price":"9219.69","order_id":"a94fa570-ff0d-4a6c-9fe7-455c0cd75748","remaining_size":"0.05423175"},{"type":"done","side":"sell","product_id":"BTC-USD","time":"2020-06-27T04:02:08.274084Z","sequence":14946197938,"order_id":"d1bc3e9c-a6e4-4a96-91b2-eaec0ed919b5","reason":"canceled","price":"9187.56","remaining_size":"0.04478512"},{"type":"received","side":"buy","product_id":"BTC-USD","time":"2020-06-27T04:02:08.280337Z","sequence":14946197939,"order_id":"2653e7a8-a305-41ea-8d06-eaf04bd21f47","order_type":"limit","size":"0.05465533","price":"9148.23","client_oid":"ba0369d5-45eb-42e1-9e5c-8436179917ae"},{"type":"open","side":"buy","product_id":"BTC-USD","time":"2020-06-27T04:02:08.280337Z","sequence":14946197940,"price":"9148.23","order_id":"2653e7a8-a305-41ea-8d06-eaf04bd21f47","remaining_size":"0.05465533"},{"type":"received","side":"sell","product_id":"BTC-USD","time":"2020-06-27T04:02:08.284552Z","sequence":14946197941,"order_id":"4bdc5e2c-0ecf-492e-bada-ba95abbebdf8","order_type":"limit","size":"0.05441678","price":"9188.35","client_oid":"e0ea19f2-42fa-4da9-be28-b682aeaeca52"},{"type":"open","side":"sell","product_id":"BTC-USD","time":"2020-06-27T04:02:08.284552Z","sequence":14946197942,"price":"9188.35","order_id":"4bdc5e2c-0ecf-492e-bada-ba95abbebdf8","remaining_size":"0.05441678"},{"type":"done","side":"sell","product_id":"BTC-USD","time":"2020-06-27T04:02:08.320257Z","sequence":14946197943,"order_id":"a42822ba-e110-4f9f-9bb8-e90e37fc15b8","reason":"canceled","price":"9231.68","remaining_size":"0.1"},{"type":"done","side":"sell","product_id":"BTC-USD","time":"2020-06-27T04:02:08.336382Z","sequence":14946197944,"order_id":"97a0a295-2736-4e0b-80ed-3a27302e785b","reason":"canceled","price":"9164.92","remaining_size":"1.17389918"},{"type":"done","side":"sell","product_id":"BTC-USD","time":"2020-06-27T04:02:08.342425Z","sequence":14946197945,"order_id":"4bdc5e2c-0ecf-492e-bada-ba95abbebdf8","reason":"canceled","price":"9188.35","remaining_size":"0.05441678"},{"type":"received","side":"sell","product_id":"BTC-USD","time":"2020-06-27T04:02:08.352660Z","sequence":14946197946,"order_id":"f1155826-b886-4502-89f2-bff0675e33b8","order_type":"limit","size":"0.03369366","price":"9187.56","client_oid":"a082e916-dcbe-44e4-adb4-92baf9d4ba6a"},{"type":"open","side":"sell","product_id":"BTC-USD","time":"2020-06-27T04:02:08.352660Z","sequence":14946197947,"price":"9187.56","order_id":"f1155826-b886-4502-89f2-bff0675e33b8","remaining_size":"0.03369366"},{"type":"done","side":"sell","product_id":"BTC-USD","time":"2020-06-27T04:02:08.364359Z","sequence":14946197948,"order_id":"97834d72-c707-491b-a280-822a4010facd","reason":"canceled","price":"9158.02","remaining_size":"0.05567108"},{"type":"done","side":"sell","product_id":"BTC-USD","time":"2020-06-27T04:02:08.376350Z","sequence":14946197949,"order_id":"8a226c6d-48ad-4649-8f8c-537c831e15f8","reason":"canceled","price":"9162.91","remaining_size":"0.819"},{"type":"done","side":"buy","product_id":"BTC-USD","time":"2020-06-27T04:02:08.380443Z","sequence":14946197950,"order_id":"8cc46811-f1c9-47bc-9362-971ae4f7e58b","reason":"canceled","price":"9153.95","remaining_size":"0.5461"},{"type":"done","side":"sell","product_id":"ETH-USD","time":"2020-06-27T04:02:08.384691Z","sequence":9591230235,"order_id":"e366d327-dbdc-4692-a1dd-1d6a4565393b","reason":"canceled","price":"229.69","remaining_size":"16.66549821"},{"type":"done","side":"sell","product_id":"ETH-USD","time":"2020-06-27T04:02:08.393073Z","sequence":9591230236,"order_id":"ea80c47a-31fd-4ea0-92bd-ae148909722e","reason":"canceled","price":"229.68","remaining_size":"23.28875237"},{"type":"done","side":"sell","product_id":"BTC-USD","time":"2020-06-27T04:02:08.389826Z","sequence":14946197951,"order_id":"f1155826-b886-4502-89f2-bff0675e33b8","reason":"canceled","price":"9187.56","remaining_size":"0.03369366"},{"type":"received","side":"sell","product_id":"BTC-USD","time":"2020-06-27T04:02:08.395576Z","sequence":14946197952,"order_id":"24ff3412-d10e-4ecd-9a7e-1cec5e842eae","order_type":"limit","size":"0.8187","price":"9165.72","client_oid":"2004461f-0035-49c1-945f-9684c0504e5f"},{"type":"open","side":"sell","product_id":"BTC-USD","time":"2020-06-27T04:02:08.395576Z","sequence":14946197953,"price":"9165.72","order_id":"24ff3412-d10e-4ecd-9a7e-1cec5e842eae","remaining_size":"0.8187"},{"type":"received","side":"sell","product_id":"BTC-USD","time":"2020-06-27T04:02:08.400793Z","sequence":14946197954,"order_id":"3552cd30-4c32-4415-8c19-6725fb7ebb81","order_type":"limit","size":"0.1","price":"9228.91","client_oid":"62fa097d-40ae-4e7d-7ea4-987f04205a06"},{"type":"open","side":"sell","product_id":"BTC-USD","time":"2020-06-27T04:02:08.400793Z","sequence":14946197955,"price":"9228.91","order_id":"3552cd30-4c32-4415-8c19-6725fb7ebb81","remaining_size":"0.1"},{"type":"received","side":"sell","product_id":"BTC-USD","time":"2020-06-27T04:02:08.400865Z","sequence":14946197956,"order_id":"4852b841-5b07-445e-a06a-b163dc694600","order_type":"limit","size":"0.02042964","price":"9186.77","client_oid":"13e8b93f-b7ac-4a51-bf82-6352c31a4001"},{"type":"open","side":"sell","product_id":"BTC-USD","time":"2020-06-27T04:02:08.400865Z","sequence":14946197957,"price":"9186.77","order_id":"4852b841-5b07-445e-a06a-b163dc694600","remaining_size":"0.02042964"},{"type":"received","side":"buy","product_id":"BTC-USD","time":"2020-06-27T04:02:08.407889Z","sequence":14946197958,"order_id":"6d206a0f-e88a-4bf6-98cb-56edb4082677","order_type":"limit","size":"0.5458","price":"9154.69","client_oid":"2001a061-d6f3-4047-825e-09f9c04bdf61"},{"type":"open","side":"buy","product_id":"BTC-USD","time":"2020-06-27T04:02:08.407889Z","sequence":14946197959,"price":"9154.69","order_id":"6d206a0f-e88a-4bf6-98cb-56edb4082677","remaining_size":"0.5458"},{"type":"received","side":"sell","product_id":"ETH-USD","time":"2020-06-27T04:02:08.412246Z","sequence":9591230237,"order_id":"f31af618-fdfc-4d4d-a2b1-5526ed9e4acf","order_type":"limit","size":"23.28875237","price":"229.69","client_oid":"c3e9f285-2ce8-3aa8-159b-e7a932000100"},{"type":"open","side":"sell","product_id":"ETH-USD","time":"2020-06-27T04:02:08.412246Z","sequence":9591230238,"price":"229.69","order_id":"f31af618-fdfc-4d4d-a2b1-5526ed9e4acf","remaining_size":"23.28875237"},{"type":"received","side":"sell","product_id":"ETH-USD","time":"2020-06-27T04:02:08.413951Z","sequence":9591230239,"order_id":"6d5f8768-b7b0-445d-bc36-059553effe35","order_type":"limit","size":"16.66582261","price":"229.67","client_oid":"cca0871e-c15e-45fe-a5a7-1da889a834fa"},{"type":"open","side":"sell","product_id":"ETH-USD","time":"2020-06-27T04:02:08.413951Z","sequence":9591230240,"price":"229.67","order_id":"6d5f8768-b7b0-445d-bc36-059553effe35","remaining_size":"16.66582261"},{"type":"received","side":"sell","product_id":"BTC-USD","time":"2020-06-27T04:02:08.419703Z","sequence":14946197960,"order_id":"2e31806a-b897-40ed-839a-c71b1f0c76d6","order_type":"limit","size":"1.17389918","price":"9163.19","client_oid":"e0a6eacc-c539-4340-afca-d6dbb4b95dd5"},{"type":"open","side":"sell","product_id":"BTC-USD","time":"2020-06-27T04:02:08.419703Z","sequence":14946197961,"price":"9163.19","order_id":"2e31806a-b897-40ed-839a-c71b1f0c76d6","remaining_size":"1.17389918"},{"type":"done","side":"sell","product_id":"BTC-USD","time":"2020-06-27T04:02:08.424132Z","sequence":14946197962,"order_id":"107bd496-ff6d-4253-9acd-3dcc50ef9f39","reason":"canceled","price":"9167.59","remaining_size":"1.06905367"},{"type":"done","side":"sell","product_id":"ETH-USD","time":"2020-06-27T04:02:08.427816Z","sequence":9591230241,"order_id":"79588776-06f7-493c-9d6f-17ba3623c883","reason":"canceled","price":"229.85","remaining_size":"0.05"},{"type":"received","side":"sell","product_id":"BTC-USD","time":"2020-06-27T04:02:08.484517Z","sequence":14946197963,"order_id":"4d87922b-c88a-4580-ae73-ad8ca701c315","order_type":"limit","size":"0.05","price":"9158.01","client_oid":"3430ff3e-5b2d-4c2c-856e-d68585754d74"},{"type":"open","side":"sell","product_id":"BTC-USD","time":"2020-06-27T04:02:08.484517Z","sequence":14946197964,"price":"9158.01","order_id":"4d87922b-c88a-4580-ae73-ad8ca701c315","remaining_size":"0.05"},{"type":"done","side":"sell","product_id":"BTC-USD","time":"2020-06-27T04:02:08.493802Z","sequence":14946197965,"order_id":"cb7d67fa-5dac-4165-ad96-cd08aaa95f3a","reason":"canceled","price":"9159.05","remaining_size":"0.539"},{"type":"received","side":"buy","product_id":"BTC-USD","time":"2020-06-27T04:02:08.498695Z","sequence":14946197966,"order_id":"72f14c43-88f0-4c40-9680-4df73b18cc1f","order_type":"market","funds":"56.7263623818","client_oid":"2617f636-13c4-46cd-ea13-2accdf42d49b"},{"type":"match","side":"sell","product_id":"BTC-USD","time":"2020-06-27T04:02:08.498695Z","sequence":14946197967,"trade_id":95662175,"maker_order_id":"448b092b-a432-4c97-a993-0e54a6e89f12","taker_order_id":"72f14c43-88f0-4c40-9680-4df73b18cc1f","size":"0.00619418","price":"9158.01"},{"type":"done","side":"buy","product_id":"BTC-USD","time":"2020-06-27T04:02:08.498695Z","sequence":14946197968,"order_id":"72f14c43-88f0-4c40-9680-4df73b18cc1f","reason":"filled"},{"type":"received","side":"sell","product_id":"BTC-USD","time":"2020-06-27T04:02:08.499112Z","sequence":14946197969,"order_id":"8678e5ed-f3ac-4e46-8097-96d8d0b51d98","order_type":"limit","size":"0.541","price":"9159.29","client_oid":"48f77910-1839-42c0-9440-e61d805ff633"},{"type":"open","side":"sell","product_id":"BTC-USD","time":"2020-06-27T04:02:08.499112Z","sequence":14946197970,"price":"9159.29","order_id":"8678e5ed-f3ac-4e46-8097-96d8d0b51d98","remaining_size":"0.541"},{"type":"received","side":"sell","product_id":"BTC-USD","time":"2020-06-27T04:02:08.501490Z","sequence":14946197971,"order_id":"7db703dd-8872-4e39-aa07-a8c3d33d194d","order_type":"limit","size":"0.541","price":"9162.04","client_oid":"ad1fb083-db24-417f-9cc6-0d7fa5b9b31e"},{"type":"open","side":"sell","product_id":"BTC-USD","time":"2020-06-27T04:02:08.501490Z","sequence":14946197972,"price":"9162.04","order_id":"7db703dd-8872-4e39-aa07-a8c3d33d194d","remaining_size":"0.541"},{"type":"done","side":"sell","product_id":"BTC-USD","time":"2020-06-27T04:02:08.508067Z","sequence":14946197973,"order_id":"4d87922b-c88a-4580-ae73-ad8ca701c315","reason":"canceled","price":"9158.01","remaining_size":"0.05"},{"type":"done","side":"sell","product_id":"BTC-USD","time":"2020-06-27T04:02:08.523654Z","sequence":14946197974,"order_id":"02b8c95d-fc94-4345-a351-bc0b7e85aa57","reason":"canceled","price":"9180.37","remaining_size":"1.06790003"},{"type":"done","side":"buy","product_id":"ETH-USD","time":"2020-06-27T04:02:08.597218Z","sequence":9591230242,"order_id":"5a55fd61-01fd-4fc2-a24c-6ab319b5efd7","reason":"canceled","price":"229.17","remaining_size":"16.66553228"},{"type":"done","side":"sell","product_id":"BTC-USD","time":"2020-06-27T04:02:08.599527Z","sequence":14946197975,"order_id":"c757e166-accd-490a-b7db-3af67812c2d9","reason":"canceled","price":"9181.47","remaining_size":"1.25316497"},{"type":"received","side":"sell","product_id":"BTC-USD","time":"2020-06-27T04:02:08.608438Z","sequence":14946197976,"order_id":"d09c471d-11ca-4c85-926e-afa451c828e3","order_type":"limit","size":"1.02478187","price":"9184.99","client_oid":"c19e3465-53d6-41f3-bffd-cbeac4f811e5"},{"type":"open","side":"sell","product_id":"BTC-USD","time":"2020-06-27T04:02:08.608438Z","sequence":14946197977,"price":"9184.99","order_id":"d09c471d-11ca-4c85-926e-afa451c828e3","remaining_size":"1.02478187"},{"type":"received","side":"sell","product_id":"BTC-USD","time":"2020-06-27T04:02:08.608438Z","sequence":14946197978,"order_id":"3781c8dd-3760-44d8-a3e5-1c339a98c9c3","order_type":"limit","size":"1.25316497","price":"9175.17","client_oid":"47d88115-29d9-4f83-833a-74a90640488b"},{"type":"open","side":"sell","product_id":"BTC-USD","time":"2020-06-27T04:02:08.608438Z","sequence":14946197979,"price":"9175.17","order_id":"3781c8dd-3760-44d8-a3e5-1c339a98c9c3","remaining_size":"1.25316497"},{"type":"received","side":"sell","product_id":"BTC-USD","time":"2020-06-27T04:02:08.608438Z","sequence":14946197980,"order_id":"6a4b7a18-00b5-4609-a262-fa15ca060f88","order_type":"limit","size":"1.06790003","price":"9172.39","client_oid":"22aa9c70-e091-4529-8a02-9ed5e09b0c0f"},{"type":"open","side":"sell","product_id":"BTC-USD","time":"2020-06-27T04:02:08.608438Z","sequence":14946197981,"price":"9172.39","order_id":"6a4b7a18-00b5-4609-a262-fa15ca060f88","remaining_size":"1.06790003"},{"type":"received","side":"buy","product_id":"ETH-USD","time":"2020-06-27T04:02:08.616688Z","sequence":9591230243,"order_id":"48314020-d448-4d54-b54a-57ff8b1413d8","order_type":"limit","size":"16.66579498","price":"229.17","client_oid":"5d901590-6211-4f20-b9bb-85001a251f31"},{"type":"open","side":"buy","product_id":"ETH-USD","time":"2020-06-27T04:02:08.616688Z","sequence":9591230244,"price":"229.17","order_id":"48314020-d448-4d54-b54a-57ff8b1413d8","remaining_size":"16.66579498"},{"type":"received","side":"sell","product_id":"BTC-USD","time":"2020-06-27T04:02:08.640082Z","sequence":14946197982,"order_id":"f0d7e39a-846b-48ec-9f19-15d378bc5c01","order_type":"limit","size":"0.05","price":"9158.01","client_oid":"4648bb49-e867-4b2e-ace6-8045c0f7e677"},{"type":"open","side":"sell","product_id":"BTC-USD","time":"2020-06-27T04:02:08.640082Z","sequence":14946197983,"price":"9158.01","order_id":"f0d7e39a-846b-48ec-9f19-15d378bc5c01","remaining_size":"0.05"},{"type":"received","side":"buy","product_id":"BTC-USD","time":"2020-06-27T04:02:08.674636Z","sequence":14946197984,"order_id":"dd1ac9ca-7d3a-47bf-ab4a-bd54a5f3847a","order_type":"limit","size":"0.36","price":"9158","client_oid":""},{"type":"open","side":"buy","product_id":"BTC-USD","time":"2020-06-27T04:02:08.674636Z","sequence":14946197985,"price":"9158","order_id":"dd1ac9ca-7d3a-47bf-ab4a-bd54a5f3847a","remaining_size":"0.36"},{"type":"received","side":"buy","product_id":"BTC-USD","time":"2020-06-27T04:02:08.747199Z","sequence":14946197986,"order_id":"e0ff2971-fa64-4a74-8f9e-aa6c47c96616","order_type":"limit","size":"0.014999","price":"9571.3","client_oid":"0341d65a-0dfb-46ad-bbe2-3a98e5752647"},{"type":"match","side":"sell","product_id":"BTC-USD","time":"2020-06-27T04:02:08.747199Z","sequence":14946197987,"trade_id":95662176,"maker_order_id":"448b092b-a432-4c97-a993-0e54a6e89f12","taker_order_id":"e0ff2971-fa64-4a74-8f9e-aa6c47c96616","size":"0.014999","price":"9158.01"},{"type":"done","side":"buy","product_id":"BTC-USD","time":"2020-06-27T04:02:08.747199Z","sequence":14946197988,"order_id":"e0ff2971-fa64-4a74-8f9e-aa6c47c96616","reason":"filled","price":"9571.3","remaining_size":"0"},{"type":"done","side":"sell","product_id":"BTC-USD","time":"2020-06-27T04:02:08.754546Z","sequence":14946197989,"order_id":"f0d7e39a-846b-48ec-9f19-15d378bc5c01","reason":"canceled","price":"9158.01","remaining_size":"0.05"},{"type":"done","side":"sell","product_id":"BTC-USD","time":"2020-06-27T04:02:08.775997Z","sequence":14946197990,"order_id":"f99c9a84-c243-4aaa-b518-0288742487cd","reason":"canceled","price":"9193.87","remaining_size":"0.01"},{"type":"received","side":"sell","product_id":"BTC-USD","time":"2020-06-27T04:02:08.785040Z","sequence":14946197991,"order_id":"bc4163c6-cd5a-445d-9351-88bb2bc69c0b","order_type":"limit","size":"0.01","price":"9193.12","client_oid":"5c98816d-c6ed-4c34-aff0-f964e969b45e"},{"type":"open","side":"sell","product_id":"BTC-USD","time":"2020-06-27T04:02:08.785040Z","sequence":14946197992,"price":"9193.12","order_id":"bc4163c6-cd5a-445d-9351-88bb2bc69c0b","remaining_size":"0.01"},{"type":"heartbeat","last_trade_id":0,"product_id":"BTC-USD","sequence":14946197992,"time":"2020-06-27T04:02:08.832525Z"},{"type":"done","side":"sell","product_id":"BTC-USD","time":"2020-06-27T04:02:08.851055Z","sequence":14946197993,"order_id":"f87e0aaa-0876-4004-ae09-1faf3d43dbfb","reason":"canceled","price":"9177.48","remaining_size":"0.30228"},{"type":"heartbeat","last_trade_id":0,"product_id":"ETH-USD","sequence":9591230244,"time":"2020-06-27T04:02:08.859252Z"},{"type":"received","side":"sell","product_id":"BTC-USD","time":"2020-06-27T04:02:08.861666Z","sequence":14946197994,"order_id":"b13c56aa-5ea4-48fc-98d9-e4f62be2d64c","order_type":"limit","size":"0.07890749","price":"9177.08","client_oid":"2f9b7e99-10cd-4e17-9c54-ca37c38c9d1f"},{"type":"open","side":"sell","product_id":"BTC-USD","time":"2020-06-27T04:02:08.861666Z","sequence":14946197995,"price":"9177.08","order_id":"b13c56aa-5ea4-48fc-98d9-e4f62be2d64c","remaining_size":"0.07890749"},{"type":"done","side":"sell","product_id":"BTC-USD","time":"2020-06-27T04:02:08.907802Z","sequence":14946197996,"order_id":"ab5842a8-bb22-4b63-88ce-42c880e9595f","reason":"canceled","price":"9393.56","remaining_size":"0.004"},{"type":"done","side":"sell","product_id":"BTC-USD","time":"2020-06-27T04:02:08.919352Z","sequence":14946197997,"order_id":"4852b841-5b07-445e-a06a-b163dc694600","reason":"canceled","price":"9186.77","remaining_size":"0.02042964"},{"type":"received","side":"sell","product_id":"BTC-USD","time":"2020-06-27T04:02:08.919868Z","sequence":14946197998,"order_id":"ac76dd14-86b5-4a5b-9391-975daf754f2b","order_type":"limit","size":"0.05","price":"9158.01","client_oid":"be8d20eb-96d8-4b97-ba9e-85a87ee274b3"},{"type":"open","side":"sell","product_id":"BTC-USD","time":"2020-06-27T04:02:08.919868Z","sequence":14946197999,"price":"9158.01","order_id":"ac76dd14-86b5-4a5b-9391-975daf754f2b","remaining_size":"0.05"},{"type":"received","side":"sell","product_id":"BTC-USD","time":"2020-06-27T04:02:08.928829Z","sequence":14946198000,"order_id":"ca787eeb-4f7e-47d6-8152-d86b38b629e2","order_type":"limit","size":"0.05442145","price":"9187.56","client_oid":"5eb3758a-4269-4c55-9d0d-e03be524a8b7"},{"type":"received","side":"sell","product_id":"ETH-USD","time":"2020-06-27T04:02:08.928960Z","sequence":9591230245,"order_id":"528d73fb-001b-4ff5-86d7-895f3b8c0d56","order_type":"limit","size":"0.05","price":"230.02","client_oid":""},{"type":"open","side":"sell","product_id":"BTC-USD","time":"2020-06-27T04:02:08.928829Z","sequence":14946198001,"price":"9187.56","order_id":"ca787eeb-4f7e-47d6-8152-d86b38b629e2","remaining_size":"0.05442145"},{"type":"open","side":"sell","product_id":"ETH-USD","time":"2020-06-27T04:02:08.928960Z","sequence":9591230246,"price":"230.02","order_id":"528d73fb-001b-4ff5-86d7-895f3b8c0d56","remaining_size":"0.05"},{"type":"done","side":"sell","product_id":"BTC-USD","time":"2020-06-27T04:02:08.940141Z","sequence":14946198002,"order_id":"ca787eeb-4f7e-47d6-8152-d86b38b629e2","reason":"canceled","price":"9187.56","remaining_size":"0.05442145"},{"type":"done","side":"sell","product_id":"ETH-USD","time":"2020-06-27T04:02:08.944500Z","sequence":9591230247,"order_id":"6d5f8768-b7b0-445d-bc36-059553effe35","reason":"canceled","price":"229.67","remaining_size":"16.66582261"},{"type":"received","side":"sell","product_id":"BTC-USD","time":"2020-06-27T04:02:08.950683Z","sequence":14946198003,"order_id":"0b9942c6-2a24-4534-9a7e-d09c2d866aeb","order_type":"limit","size":"0.0541233","price":"9188.35","client_oid":"4a100d26-d6f3-4453-9970-a5989b5597af"},{"type":"open","side":"sell","product_id":"BTC-USD","time":"2020-06-27T04:02:08.950683Z","sequence":14946198004,"price":"9188.35","order_id":"0b9942c6-2a24-4534-9a7e-d09c2d866aeb","remaining_size":"0.0541233"},{"type":"done","side":"sell","product_id":"BTC-USD","time":"2020-06-27T04:02:08.968344Z","sequence":14946198005,"order_id":"0b9942c6-2a24-4534-9a7e-d09c2d866aeb","reason":"canceled","price":"9188.35","remaining_size":"0.0541233"},{"type":"done","side":"buy","product_id":"ETH-USD","time":"2020-06-27T04:02:08.976291Z","sequence":9591230248,"order_id":"533bb011-17a6-4753-aaa1-df795e733d34","reason":"canceled","price":"228.61","remaining_size":"106.59959848"},{"type":"received","side":"sell","product_id":"ETH-USD","time":"2020-06-27T04:02:08.976291Z","sequence":9591230249,"order_id":"fa588f0d-a484-4348-8d01-75356697fa22","order_type":"limit","size":"16.66580214","price":"229.67","client_oid":"70a99fff-b23e-4149-81ca-2d329a135cdf"},{"type":"open","side":"sell","product_id":"ETH-USD","time":"2020-06-27T04:02:08.976291Z","sequence":9591230250,"price":"229.67","order_id":"fa588f0d-a484-4348-8d01-75356697fa22","remaining_size":"16.66580214"},{"type":"received","side":"sell","product_id":"BTC-USD","time":"2020-06-27T04:02:08.977796Z","sequence":14946198006,"order_id":"33d1d9a9-28e8-403f-aaa7-f62781df1a35","order_type":"limit","size":"0.04478512","price":"9186.77","client_oid":"f675a535-d3f0-4a37-9057-7261aadf4a47"},{"type":"open","side":"sell","product_id":"BTC-USD","time":"2020-06-27T04:02:08.977796Z","sequence":14946198007,"price":"9186.77","order_id":"33d1d9a9-28e8-403f-aaa7-f62781df1a35","remaining_size":"0.04478512"},{"type":"done","side":"sell","product_id":"BTC-USD","time":"2020-06-27T04:02:09.017017Z","sequence":14946198008,"order_id":"af38f30b-38f4-4c1e-a28e-3d5689980f1c","reason":"canceled","price":"9333.56","remaining_size":"0.003"},{"type":"done","side":"sell","product_id":"BTC-USD","time":"2020-06-27T04:02:09.077523Z","sequence":14946198009,"order_id":"bc4163c6-cd5a-445d-9351-88bb2bc69c0b","reason":"canceled","price":"9193.12","remaining_size":"0.01"},{"type":"done","side":"sell","product_id":"BTC-USD","time":"2020-06-27T04:02:09.091021Z","sequence":14946198010,"order_id":"ac76dd14-86b5-4a5b-9391-975daf754f2b","reason":"canceled","price":"9158.01","remaining_size":"0.05"},{"type":"received","side":"sell","product_id":"BTC-USD","time":"2020-06-27T04:02:09.092329Z","sequence":14946198011,"order_id":"034daf3b-10fe-4ef8-ab49-e4f274ba78e4","order_type":"limit","size":"0.05244353","price":"9193.49","client_oid":"01863899-4a5b-47c2-a6be-0573fc9df45a"},{"type":"open","side":"sell","product_id":"BTC-USD","time":"2020-06-27T04:02:09.092329Z","sequence":14946198012,"price":"9193.49","order_id":"034daf3b-10fe-4ef8-ab49-e4f274ba78e4","remaining_size":"0.05244353"},{"type":"received","side":"sell","product_id":"BTC-USD","time":"2020-06-27T04:02:09.104039Z","sequence":14946198013,"order_id":"19a5d907-6077-428f-88c0-ca910a1a2bbb","order_type":"limit","size":"0.05","price":"9158.01","client_oid":"9b173a75-f204-4938-9445-14bd633fa4b5"},{"type":"open","side":"sell","product_id":"BTC-USD","time":"2020-06-27T04:02:09.104039Z","sequence":14946198014,"price":"9158.01","order_id":"19a5d907-6077-428f-88c0-ca910a1a2bbb","remaining_size":"0.05"},{"type":"done","side":"sell","product_id":"BTC-USD","time":"2020-06-27T04:02:09.125003Z","sequence":14946198015,"order_id":"c86dddc0-8932-4efc-a59f-cf712e5d2118","reason":"canceled","price":"9273.56","remaining_size":"0.002"},{"type":"received","side":"buy","product_id":"BTC-USD","time":"2020-06-27T04:02:09.140008Z","sequence":14946198016,"order_id":"475bd6e3-8050-4e2e-a163-8f30429300ce","order_type":"limit","size":"0.3","price":"9155.36","client_oid":"f8d8af65-b82a-11ea-a5d7-0a070dc90c3f"},{"type":"open","side":"buy","product_id":"BTC-USD","time":"2020-06-27T04:02:09.140008Z","sequence":14946198017,"price":"9155.36","order_id":"475bd6e3-8050-4e2e-a163-8f30429300ce","remaining_size":"0.3"},{"type":"done","side":"sell","product_id":"BTC-USD","time":"2020-06-27T04:02:09.186607Z","sequence":14946198018,"order_id":"19a5d907-6077-428f-88c0-ca910a1a2bbb","reason":"canceled","price":"9158.01","remaining_size":"0.05"},{"type":"done","side":"sell","product_id":"BTC-USD","time":"2020-06-27T04:02:09.262201Z","sequence":14946198019,"order_id":"6184794a-c025-4a4c-8ec2-83c321a99859","reason":"canceled","price":"9213.56","remaining_size":"0.001"},{"type":"received","side":"buy","product_id":"BTC-USD","time":"2020-06-27T04:02:09.344167Z","sequence":14946198020,"order_id":"79f1db5d-5359-4065-85bd-e7409a9072a9","order_type":"limit","size":"0.5","price":"9147.54","client_oid":""},{"type":"open","side":"buy","product_id":"BTC-USD","time":"2020-06-27T04:02:09.344167Z","sequence":14946198021,"price":"9147.54","order_id":"79f1db5d-5359-4065-85bd-e7409a9072a9","remaining_size":"0.5"},{"type":"received","side":"buy","product_id":"BTC-USD","time":"2020-06-27T04:02:09.360061Z","sequence":14946198022,"order_id":"5d94d6e9-6c00-42d9-b78c-54aac5d848e9","order_type":"limit","size":"0.04816114","price":"9155.36","client_oid":"281dd1d8-331e-43d4-91d2-4ca2464818aa"},{"type":"open","side":"buy","product_id":"BTC-USD","time":"2020-06-27T04:02:09.360061Z","sequence":14946198023,"price":"9155.36","order_id":"5d94d6e9-6c00-42d9-b78c-54aac5d848e9","remaining_size":"0.04816114"},{"type":"done","side":"buy","product_id":"BTC-USD","time":"2020-06-27T04:02:09.376834Z","sequence":14946198024,"order_id":"ceed251b-7326-4b37-b505-ba6999779966","reason":"canceled","price":"8970.48","remaining_size":"0.004"},{"type":"done","side":"sell","product_id":"BTC-USD","time":"2020-06-27T04:02:09.381143Z","sequence":14946198025,"order_id":"eee65faf-4678-45ae-8faa-a42ee43230dc","reason":"canceled","price":"9159.1","remaining_size":"0.1637"}]